Workbook
Name LME: PainelDeVariaveis!$K$3
Name VME: PainelDeVariaveis!$K$4

Sheet Catalogo de Variaveis
F1: Média | G1: =AVERAGE(G14:G34) -> 0.57142857 | H1: =AVERAGE(H14:H34) -> 12.857143 | I1: =AVERAGE(I14:I34) -> 0.38095238 | J1: =AVERAGE(J14:J34) -> 12.857143 | M1: =AVERAGE(M14:M34) -> 9.3809524 | N1: =AVERAGE(N14:N34) -> 10.619048 | O1: =AVERAGE(O14:O34) -> 1.2380952 | P1: =AVERAGE(P14:P34) -> 10.619048
F2: Desvio Padrão | G2: =_xlfn.STDEV.S(G14:G34) -> 0.74642003 | H2: =_xlfn.STDEV.S(H14:H34) -> 3.8116363 | I2: =_xlfn.STDEV.S(I14:I34) -> 0.58959227 | J2: =_xlfn.STDEV.S(J14:J34) -> 3.8116363 | M2: =_xlfn.STDEV.S(M14:M34) -> 18.42139 | N2: =_xlfn.STDEV.S(N14:N34) -> 20.912858 | O2: =_xlfn.STDEV.S(O14:O34) -> 3.374978 | P2: =_xlfn.STDEV.S(P14:P34) -> 20.912858
F3: Máximo | G3: =MAX(G14:G34) -> 2 | H3: =MAX(H14:H34) -> 20 | I3: =MAX(I14:I34) -> 2 | J3: =MAX(J14:J34) -> 20 | M3: =MAX(M14:M34) -> 55 | N3: =MAX(N14:N34) -> 65 | O3: =MAX(O14:O34) -> 12 | P3: =MAX(P14:P34) -> 65
F4: Mínimo | G4: =MIN(G14:G34) -> 0 | H4: =MIN(H14:H34) -> 6 | I4: =MIN(I14:I34) -> 0 | J4: =MIN(J14:J34) -> 6 | M4: =MIN(M14:M34) -> 0 | N4: =MIN(N14:N34) -> 0 | O4: =MIN(O14:O34) -> 0 | P4: =MIN(P14:P34) -> 0
A5: Ano | B5: Bim | C5: Trim | D5: Quad | E5: Sem | F5: PERIODO | G5: V01 | H5: V02 | I5: V03 | J5: V04 | K5: V05 | L5: V06 | M5: V07 | N5: V08 | O5: V09 | P5: V10 | Q5: V11 | R5: V12 | S5: V13 | T5: V14 | U5: V15
F6: 44562
F7: 44593
F8: 44621
F9: 44652
F10: 44682
F11: 44713
F12: 44743
F13: 44774
A14: =YEAR(F14) -> 2022 | B14: =ROUNDUP(MONTH(F14)/2,0) -> 5 | C14: =ROUNDUP(MONTH(F14)/3,0) -> 3 | D14: =ROUNDUP(MONTH(F14)/4,0) -> 3 | E14: =ROUNDUP(MONTH(F14)/6,0) -> 2 | F14: 44805 | G14: 1 | H14: 16 | I14: 0 | J14: 16 | K14: 0 | L14: 0 | M14: 0 | N14: 0 | O14: 0 | P14: 0 | Q14: 0 | R14: 0 | S14: 6 | T14: 6 | U14: 6
A15: =YEAR(F15) -> 2022 | B15: =ROUNDUP(MONTH(F15)/2,0) -> 5 | C15: =ROUNDUP(MONTH(F15)/3,0) -> 4 | D15: =ROUNDUP(MONTH(F15)/4,0) -> 3 | E15: =ROUNDUP(MONTH(F15)/6,0) -> 2 | F15: 44835 | G15: 0 | H15: 13 | I15: 1 | J15: 13 | K15: 0 | L15: 0 | M15: 0 | N15: 0 | O15: 0 | P15: 0 | Q15: 1 | R15: 0 | S15: 4 | T15: 4 | U15: 4
A16: =YEAR(F16) -> 2022 | B16: =ROUNDUP(MONTH(F16)/2,0) -> 6 | C16: =ROUNDUP(MONTH(F16)/3,0) -> 4 | D16: =ROUNDUP(MONTH(F16)/4,0) -> 3 | E16: =ROUNDUP(MONTH(F16)/6,0) -> 2 | F16: 44866 | G16: 0 | H16: 9 | I16: 0 | J16: 9 | K16: 0 | L16: 0 | M16: 0 | N16: 0 | O16: 0 | P16: 0 | Q16: 0 | R16: 0 | S16: 8 | T16: 8 | U16: 8
A17: =YEAR(F17) -> 2022 | B17: =ROUNDUP(MONTH(F17)/2,0) -> 6 | C17: =ROUNDUP(MONTH(F17)/3,0) -> 4 | D17: =ROUNDUP(MONTH(F17)/4,0) -> 3 | E17: =ROUNDUP(MONTH(F17)/6,0) -> 2 | F17: 44896 | G17: 0 | H17: 7 | I17: 1 | J17: 7 | K17: 0 | L17: 0 | M17: 0 | N17: 0 | O17: 0 | P17: 0 | Q17: 0 | R17: 1 | S17: 2 | T17: 2 | U17: 2
A18: =YEAR(F18) -> 2023 | B18: =ROUNDUP(MONTH(F18)/2,0) -> 1 | C18: =ROUNDUP(MONTH(F18)/3,0) -> 1 | D18: =ROUNDUP(MONTH(F18)/4,0) -> 1 | E18: =ROUNDUP(MONTH(F18)/6,0) -> 1 | F18: 44927 | G18: 0 | H18: 6 | I18: 0 | J18: 6 | K18: 0 | L18: 0 | M18: 0 | N18: 0 | O18: 0 | P18: 0 | Q18: 0 | R18: 0 | S18: 2 | T18: 2 | U18: 2
A19: =YEAR(F19) -> 2023 | B19: =ROUNDUP(MONTH(F19)/2,0) -> 1 | C19: =ROUNDUP(MONTH(F19)/3,0) -> 1 | D19: =ROUNDUP(MONTH(F19)/4,0) -> 1 | E19: =ROUNDUP(MONTH(F19)/6,0) -> 1 | F19: 44958 | G19: 2 | H19: 14 | I19: 0 | J19: 14 | K19: 0 | L19: 0 | M19: 0 | N19: 0 | O19: 0 | P19: 0 | Q19: 0 | R19: 0 | S19: 2 | T19: 2 | U19: 2
A20: =YEAR(F20) -> 2023 | B20: =ROUNDUP(MONTH(F20)/2,0) -> 2 | C20: =ROUNDUP(MONTH(F20)/3,0) -> 1 | D20: =ROUNDUP(MONTH(F20)/4,0) -> 1 | E20: =ROUNDUP(MONTH(F20)/6,0) -> 1 | F20: 44986 | G20: 0 | H20: 11 | I20: 0 | J20: 11 | K20: 0 | L20: 0 | M20: 30 | N20: 42 | O20: 12 | P20: 42 | Q20: 0 | R20: 0 | S20: 8 | T20: 8 | U20: 8
A21: =YEAR(F21) -> 2023 | B21: =ROUNDUP(MONTH(F21)/2,0) -> 2 | C21: =ROUNDUP(MONTH(F21)/3,0) -> 2 | D21: =ROUNDUP(MONTH(F21)/4,0) -> 1 | E21: =ROUNDUP(MONTH(F21)/6,0) -> 1 | F21: 45017 | G21: 0 | H21: 12 | I21: 0 | J21: 12 | K21: 0 | L21: 0 | M21: 50 | N21: 54 | O21: 4 | P21: 54 | Q21: 1 | R21: 0 | S21: 4 | T21: 4 | U21: 4
A22: =YEAR(F22) -> 2023 | B22: =ROUNDUP(MONTH(F22)/2,0) -> 3 | C22: =ROUNDUP(MONTH(F22)/3,0) -> 2 | D22: =ROUNDUP(MONTH(F22)/4,0) -> 2 | E22: =ROUNDUP(MONTH(F22)/6,0) -> 1 | F22: 45047 | G22: 0 | H22: 15 | I22: 0 | J22: 15 | K22: 0 | L22: 0 | M22: 0 | N22: 0 | O22: 0 | P22: 0 | Q22: 0 | R22: 0 | S22: 4 | T22: 4 | U22: 4
A23: =YEAR(F23) -> 2023 | B23: =ROUNDUP(MONTH(F23)/2,0) -> 3 | C23: =ROUNDUP(MONTH(F23)/3,0) -> 2 | D23: =ROUNDUP(MONTH(F23)/4,0) -> 2 | E23: =ROUNDUP(MONTH(F23)/6,0) -> 1 | F23: 45078 | G23: 1 | H23: 9 | I23: 2 | J23: 9 | K23: 0 | L23: 0 | M23: 43 | N23: 43 | O23: 0 | P23: 43 | Q23: 0 | R23: 0 | S23: 7 | T23: 7 | U23: 7
A24: =YEAR(F24) -> 2023 | B24: =ROUNDUP(MONTH(F24)/2,0) -> 4 | C24: =ROUNDUP(MONTH(F24)/3,0) -> 3 | D24: =ROUNDUP(MONTH(F24)/4,0) -> 2 | E24: =ROUNDUP(MONTH(F24)/6,0) -> 2 | F24: 45108 | G24: 2 | H24: 16 | I24: 1 | J24: 16 | K24: 0 | L24: 0 | M24: 0 | N24: 0 | O24: 0 | P24: 0 | Q24: 0 | R24: 0 | S24: 5 | T24: 5 | U24: 5
A25: =YEAR(F25) -> 2023 | B25: =ROUNDUP(MONTH(F25)/2,0) -> 4 | C25: =ROUNDUP(MONTH(F25)/3,0) -> 3 | D25: =ROUNDUP(MONTH(F25)/4,0) -> 2 | E25: =ROUNDUP(MONTH(F25)/6,0) -> 2 | F25: 45139 | G25: 2 | H25: 14 | I25: 0 | J25: 14 | K25: 0 | L25: 0 | M25: 55 | N25: 65 | O25: 10 | P25: 65 | Q25: 0 | R25: 0 | S25: 6 | T25: 6 | U25: 6
... A51: =YEAR(F51) -> 2025 | B51: =ROUNDUP(MONTH(F51)/2,0) -> 5 | C51: =ROUNDUP(MONTH(F51)/3,0) -> 4 | D51: =ROUNDUP(MONTH(F51)/4,0) -> 3 | E51: =ROUNDUP(MONTH(F51)/6,0) -> 2 | F51: 45931 | G51: 0 | H51: 14 | I51: 2 | J51: 14 | K51: 10 | L51: 9 | M51: 41 | N51: 47 | O51: 6 | P51: 47 | Q51: 2 | R51: 0 | S51: 0 | T51: 0 | U51: 0
A52: =YEAR(F52) -> 2025 | B52: =ROUNDUP(MONTH(F52)/2,0) -> 6 | C52: =ROUNDUP(MONTH(F52)/3,0) -> 4 | D52: =ROUNDUP(MONTH(F52)/4,0) -> 3 | E52: =ROUNDUP(MONTH(F52)/6,0) -> 2 | F52: 45962
A53: =YEAR(F53) -> 2025 | B53: =ROUNDUP(MONTH(F53)/2,0) -> 6 | C53: =ROUNDUP(MONTH(F53)/3,0) -> 4 | D53: =ROUNDUP(MONTH(F53)/4,0) -> 3 | E53: =ROUNDUP(MONTH(F53)/6,0) -> 2 | F53: 45992
A54: =YEAR(F54) -> 2026 | B54: =ROUNDUP(MONTH(F54)/2,0) -> 1 | C54: =ROUNDUP(MONTH(F54)/3,0) -> 1 | D54: =ROUNDUP(MONTH(F54)/4,0) -> 1 | E54: =ROUNDUP(MONTH(F54)/6,0) -> 1 | F54: 46023
A55: =YEAR(F55) -> 2026 | B55: =ROUNDUP(MONTH(F55)/2,0) -> 1 | C55: =ROUNDUP(MONTH(F55)/3,0) -> 1 | D55: =ROUNDUP(MONTH(F55)/4,0) -> 1 | E55: =ROUNDUP(MONTH(F55)/6,0) -> 1 | F55: 46054
A56: =YEAR(F56) -> 2026 | B56: =ROUNDUP(MONTH(F56)/2,0) -> 2 | C56: =ROUNDUP(MONTH(F56)/3,0) -> 1 | D56: =ROUNDUP(MONTH(F56)/4,0) -> 1 | E56: =ROUNDUP(MONTH(F56)/6,0) -> 1 | F56: 46082
A57: =YEAR(F57) -> 2026 | B57: =ROUNDUP(MONTH(F57)/2,0) -> 2 | C57: =ROUNDUP(MONTH(F57)/3,0) -> 2 | D57: =ROUNDUP(MONTH(F57)/4,0) -> 1 | E57: =ROUNDUP(MONTH(F57)/6,0) -> 1 | F57: 46113
A58: =YEAR(F58) -> 2026 | B58: =ROUNDUP(MONTH(F58)/2,0) -> 3 | C58: =ROUNDUP(MONTH(F58)/3,0) -> 2 | D58: =ROUNDUP(MONTH(F58)/4,0) -> 2 | E58: =ROUNDUP(MONTH(F58)/6,0) -> 1 | F58: 46143
A59: =YEAR(F59) -> 2026 | B59: =ROUNDUP(MONTH(F59)/2,0) -> 3 | C59: =ROUNDUP(MONTH(F59)/3,0) -> 2 | D59: =ROUNDUP(MONTH(F59)/4,0) -> 2 | E59: =ROUNDUP(MONTH(F59)/6,0) -> 1 | F59: 46174
A60: =YEAR(F60) -> 2026 | B60: =ROUNDUP(MONTH(F60)/2,0) -> 4 | C60: =ROUNDUP(MONTH(F60)/3,0) -> 3 | D60: =ROUNDUP(MONTH(F60)/4,0) -> 2 | E60: =ROUNDUP(MONTH(F60)/6,0) -> 2 | F60: 46204
A61: =YEAR(F61) -> 2026 | B61: =ROUNDUP(MONTH(F61)/2,0) -> 4 | C61: =ROUNDUP(MONTH(F61)/3,0) -> 3 | D61: =ROUNDUP(MONTH(F61)/4,0) -> 2 | E61: =ROUNDUP(MONTH(F61)/6,0) -> 2 | F61: 46235
A62: =YEAR(F62) -> 2026 | B62: =ROUNDUP(MONTH(F62)/2,0) -> 5 | C62: =ROUNDUP(MONTH(F62)/3,0) -> 3 | D62: =ROUNDUP(MONTH(F62)/4,0) -> 3 | E62: =ROUNDUP(MONTH(F62)/6,0) -> 2 | F62: 46266
A63: =YEAR(F63) -> 2026 | B63: =ROUNDUP(MONTH(F63)/2,0) -> 5 | C63: =ROUNDUP(MONTH(F63)/3,0) -> 4 | D63: =ROUNDUP(MONTH(F63)/4,0) -> 3 | E63: =ROUNDUP(MONTH(F63)/6,0) -> 2 | F63: 46296
... A65: =YEAR(F65) -> 2026 | B65: =ROUNDUP(MONTH(F65)/2,0) -> 6 | C65: =ROUNDUP(MONTH(F65)/3,0) -> 4 | D65: =ROUNDUP(MONTH(F65)/4,0) -> 3 | E65: =ROUNDUP(MONTH(F65)/6,0) -> 2 | F65: 46357

Sheet V01
A1: Média | B1: =AVERAGE(B9:B1048576) -> 3.9210526 | C1: =AVERAGE(C9:C1048576) -> 0.046052632 | I1: LME | J1: =IF(LME="","",LME)
A2: Desvio Padrão | B2: =_xlfn.STDEV.S(B9:B1048576) -> 2.4646866 | C2: =_xlfn.STDEV.S(C9:C1048576) -> 0.34804116 | I2: VME | J2: =IF(VME="","",VME/3)
A3: Máximo | B3: =MAX(B9:B1048576) -> 9 | C3: =MAX(C9:C1048576) -> 0.75
A4: Mínimo | B4: =MIN(B9:B1048576) -> 0 | C4: =MIN(C9:C1048576) -> -0.75
A5: V01 - NÚMERO DE DENÚNCIAS DE ASSÉDIO MORAL APURADAS NO PERÍODO RECEBIDAS PELOS DIVERSOS CANAIS DE DENÚNCIAS DA COMPANHIA
A7: DADOS | D7: SOMA | K7: AMPLITUDE
A8: Período | B8: Soma | C8: Amplitude | D8: LIC | E8: L2I | F8: L1I | G8: LMC | H8: L1S | I8: L2S | J8: LSC | K8: LIC | L8: L2I | M8: L1I | N8: LMC | O8: L1S | P8: L2S | Q8: LSC
A9: 44805 | B9: =IF('Catalogo de Variaveis'!G14="","",SUM('Catalogo de Variaveis'!G11:G14)) -> 1 | C9: =IFERROR(IF($B9="","",AVERAGE('Catalogo de Variaveis'!G14-'Catalogo de Variaveis'!G13,'Catalogo de Variaveis'!G13-'Catalogo de Variaveis'!G12,'Catalogo de Variaveis'!G12-'Catalogo de Variaveis'!G11,'Catalogo de Variaveis'!G11-'Catalogo de Variaveis'!G10)),0) -> 0.25 | D9: =IF($B9="","",IF(OR($J$1="",$J$2=""),$B$1-3*$B$2,$J$1-3*$J$2)) -> -3.4730071 | E9: =IF($B9="","",IF(OR($J$1="",$J$2=""),$B$1-2*$B$2,$J$1-2*$J$2)) -> -1.0083205 | F9: =IF($B9="","",IF(OR($J$1="",$J$2=""),$B$1-$B$2,$J$1-$J$2)) -> 1.4563661 | G9: =IF($B9="","",IF(OR($J$1="",$J$2=""),$B$1,$J$1)) -> 3.9210526 | H9: =IF($B9="","",IF(OR($J$1="",$J$2=""),$B$1+$B$2,$J$1+$J$2)) -> 6.3857392 | I9: =IF($B9="","",IF(OR($J$1="",$J$2=""),$B$1+2*$B$2,$J$1+2*$J$2)) -> 8.8504258 | J9: =IF($B9="","",IF(OR($J$1="",$J$2=""),$B$1+3*$B$2,$J$1+3*$J$2)) -> 11.315112 | K9: =IF($B9="","",$C$1-3*$C$2) -> -0.99807083 | L9: =IF($B9="","",$C$1-2*$C$2) -> -0.65002968 | M9: =IF($B9="","",$C$1-$C$2) -> -0.30198852 | N9: =IF($B9="","",$C$1) -> 0.046052632 | O9: =IF($B9="","",$C$1+1*$C$2) -> 0.39409379 | P9: =IF($B9="","",$C$1+2*$C$2) -> 0.74213494 | Q9: =IF($B9="","",$C$1+3*$C$2) -> 1.0901761
A10: 44835 | B10: =IF('Catalogo de Variaveis'!G15="","",SUM('Catalogo de Variaveis'!G12:G15)) -> 1 | C10: =IFERROR(IF($B10="","",AVERAGE('Catalogo de Variaveis'!G15-'Catalogo de Variaveis'!G14,'Catalogo de Variaveis'!G14-'Catalogo de Variaveis'!G13,'Catalogo de Variaveis'!G13-'Catalogo de Variaveis'!G12,'Catalogo de Variaveis'!G12-'Catalogo de Variaveis'!G11)),0) -> 0 | D10: =IF($B10="","",IF(OR($J$1="",$J$2=""),$B$1-3*$B$2,$J$1-3*$J$2)) -> -3.4730071 | E10: =IF($B10="","",IF(OR($J$1="",$J$2=""),$B$1-2*$B$2,$J$1-2*$J$2)) -> -1.0083205 | F10: =IF($B10="","",IF(OR($J$1="",$J$2=""),$B$1-$B$2,$J$1-$J$2)) -> 1.4563661 | G10: =IF($B10="","",IF(OR($J$1="",$J$2=""),$B$1,$J$1)) -> 3.9210526 | H10: =IF($B10="","",IF(OR($J$1="",$J$2=""),$B$1+$B$2,$J$1+$J$2)) -> 6.3857392 | I10: =IF($B10="","",IF(OR($J$1="",$J$2=""),$B$1+2*$B$2,$J$1+2*$J$2)) -> 8.8504258 | J10: =IF($B10="","",IF(OR($J$1="",$J$2=""),$B$1+3*$B$2,$J$1+3*$J$2)) -> 11.315112 | K10: =IF($B10="","",$C$1-3*$C$2) -> -0.99807083 | L10: =IF($B10="","",$C$1-2*$C$2) -> -0.65002968 | M10: =IF($B10="","",$C$1-$C$2) -> -0.30198852 | N10: =IF($B10="","",$C$1) -> 0.046052632 | O10: =IF($B10="","",$C$1+1*$C$2) -> 0.39409379 | P10: =IF($B10="","",$C$1+2*$C$2) -> 0.74213494 | Q10: =IF($B10="","",$C$1+3*$C$2) -> 1.0901761
A11: 44866 | B11: =IF('Catalogo de Variaveis'!G16="","",SUM('Catalogo de Variaveis'!G13:G16)) -> 1 | C11: =IFERROR(IF($B11="","",AVERAGE('Catalogo de Variaveis'!G16-'Catalogo de Variaveis'!G15,'Catalogo de Variaveis'!G15-'Catalogo de Variaveis'!G14,'Catalogo de Variaveis'!G14-'Catalogo de Variaveis'!G13,'Catalogo de Variaveis'!G13-'Catalogo de Variaveis'!G12)),0) -> 0 | D11: =IF($B11="","",IF(OR($J$1="",$J$2=""),$B$1-3*$B$2,$J$1-3*$J$2)) -> -3.4730071 | E11: =IF($B11="","",IF(OR($J$1="",$J$2=""),$B$1-2*$B$2,$J$1-2*$J$2)) -> -1.0083205 | F11: =IF($B11="","",IF(OR($J$1="",$J$2=""),$B$1-$B$2,$J$1-$J$2)) -> 1.4563661 | G11: =IF($B11="","",IF(OR($J$1="",$J$2=""),$B$1,$J$1)) -> 3.9210526 | H11: =IF($B11="","",IF(OR($J$1="",$J$2=""),$B$1+$B$2,$J$1+$J$2)) -> 6.3857392 | I11: =IF($B11="","",IF(OR($J$1="",$J$2=""),$B$1+2*$B$2,$J$1+2*$J$2)) -> 8.8504258 | J11: =IF($B11="","",IF(OR($J$1="",$J$2=""),$B$1+3*$B$2,$J$1+3*$J$2)) -> 11.315112 | K11: =IF($B11="","",$C$1-3*$C$2) -> -0.99807083 | L11: =IF($B11="","",$C$1-2*$C$2) -> -0.65002968 | M11: =IF($B11="","",$C$1-$C$2) -> -0.30198852 | N11: =IF($B11="","",$C$1) -> 0.046052632 | O11: =IF($B11="","",$C$1+1*$C$2) -> 0.39409379 | P11: =IF($B11="","",$C$1+2*$C$2) -> 0.74213494 | Q11: =IF($B11="","",$C$1+3*$C$2) -> 1.0901761
A12: 44896 | B12: =IF('Catalogo de Variaveis'!G17="","",SUM('Catalogo de Variaveis'!G14:G17)) -> 1 | C12: =IFERROR(IF($B12="","",AVERAGE('Catalogo de Variaveis'!G17-'Catalogo de Variaveis'!G16,'Catalogo de Variaveis'!G16-'Catalogo de Variaveis'!G15,'Catalogo de Variaveis'!G15-'Catalogo de Variaveis'!G14,'Catalogo de Variaveis'!G14-'Catalogo de Variaveis'!G13)),0) -> 0 | D12: =IF($B12="","",IF(OR($J$1="",$J$2=""),$B$1-3*$B$2,$J$1-3*$J$2)) -> -3.4730071 | E12: =IF($B12="","",IF(OR($J$1="",$J$2=""),$B$1-2*$B$2,$J$1-2*$J$2)) -> -1.0083205 | F12: =IF($B12="","",IF(OR($J$1="",$J$2=""),$B$1-$B$2,$J$1-$J$2)) -> 1.4563661 | G12: =IF($B12="","",IF(OR($J$1="",$J$2=""),$B$1,$J$1)) -> 3.9210526 | H12: =IF($B12="","",IF(OR($J$1="",$J$2=""),$B$1+$B$2,$J$1+$J$2)) -> 6.3857392 | I12: =IF($B12="","",IF(OR($J$1="",$J$2=""),$B$1+2*$B$2,$J$1+2*$J$2)) -> 8.8504258 | J12: =IF($B12="","",IF(OR($J$1="",$J$2=""),$B$1+3*$B$2,$J$1+3*$J$2)) -> 11.315112 | K12: =IF($B12="","",$C$1-3*$C$2) -> -0.99807083 | L12: =IF($B12="","",$C$1-2*$C$2) -> -0.65002968 | M12: =IF($B12="","",$C$1-$C$2) -> -0.30198852 | N12: =IF($B12="","",$C$1) -> 0.046052632 | O12: =IF($B12="","",$C$1+1*$C$2) -> 0.39409379 | P12: =IF($B12="","",$C$1+2*$C$2) -> 0.74213494 | Q12: =IF($B12="","",$C$1+3*$C$2) -> 1.0901761
A13: 44927 | B13: =IF('Catalogo de Variaveis'!G18="","",SUM('Catalogo de Variaveis'!G15:G18)) -> 0 | C13: =IFERROR(IF($B13="","",AVERAGE('Catalogo de Variaveis'!G18-'Catalogo de Variaveis'!G17,'Catalogo de Variaveis'!G17-'Catalogo de Variaveis'!G16,'Catalogo de Variaveis'!G16-'Catalogo de Variaveis'!G15,'Catalogo de Variaveis'!G15-'Catalogo de Variaveis'!G14)),0) -> -0.25 | D13: =IF($B13="","",IF(OR($J$1="",$J$2=""),$B$1-3*$B$2,$J$1-3*$J$2)) -> -3.4730071 | E13: =IF($B13="","",IF(OR($J$1="",$J$2=""),$B$1-2*$B$2,$J$1-2*$J$2)) -> -1.0083205 | F13: =IF($B13="","",IF(OR($J$1="",$J$2=""),$B$1-$B$2,$J$1-$J$2)) -> 1.4563661 | G13: =IF($B13="","",IF(OR($J$1="",$J$2=""),$B$1,$J$1)) -> 3.9210526 | H13: =IF($B13="","",IF(OR($J$1="",$J$2=""),$B$1+$B$2,$J$1+$J$2)) -> 6.3857392 | I13: =IF($B13="","",IF(OR($J$1="",$J$2=""),$B$1+2*$B$2,$J$1+2*$J$2)) -> 8.8504258 | J13: =IF($B13="","",IF(OR($J$1="",$J$2=""),$B$1+3*$B$2,$J$1+3*$J$2)) -> 11.315112 | K13: =IF($B13="","",$C$1-3*$C$2) -> -0.99807083 | L13: =IF($B13="","",$C$1-2*$C$2) -> -0.65002968 | M13: =IF($B13="","",$C$1-$C$2) -> -0.30198852 | N13: =IF($B13="","",$C$1) -> 0.046052632 | O13: =IF($B13="","",$C$1+1*$C$2) -> 0.39409379 | P13: =IF($B13="","",$C$1+2*$C$2) -> 0.74213494 | Q13: =IF($B13="","",$C$1+3*$C$2) -> 1.0901761
A14: 44958 | B14: =IF('Catalogo de Variaveis'!G19="","",SUM('Catalogo de Variaveis'!G16:G19)) -> 2 | C14: =IFERROR(IF($B14="","",AVERAGE('Catalogo de Variaveis'!G19-'Catalogo de Variaveis'!G18,'Catalogo de Variaveis'!G18-'Catalogo de Variaveis'!G17,'Catalogo de Variaveis'!G17-'Catalogo de Variaveis'!G16,'Catalogo de Variaveis'!G16-'Catalogo de Variaveis'!G15)),0) -> 0.5 | D14: =IF($B14="","",IF(OR($J$1="",$J$2=""),$B$1-3*$B$2,$J$1-3*$J$2)) -> -3.4730071 | E14: =IF($B14="","",IF(OR($J$1="",$J$2=""),$B$1-2*$B$2,$J$1-2*$J$2)) -> -1.0083205 | F14: =IF($B14="","",IF(OR($J$1="",$J$2=""),$B$1-$B$2,$J$1-$J$2)) -> 1.4563661 | G14: =IF($B14="","",IF(OR($J$1="",$J$2=""),$B$1,$J$1)) -> 3.9210526 | H14: =IF($B14="","",IF(OR($J$1="",$J$2=""),$B$1+$B$2,$J$1+$J$2)) -> 6.3857392 | I14: =IF($B14="","",IF(OR($J$1="",$J$2=""),$B$1+2*$B$2,$J$1+2*$J$2)) -> 8.8504258 | J14: =IF($B14="","",IF(OR($J$1="",$J$2=""),$B$1+3*$B$2,$J$1+3*$J$2)) -> 11.315112 | K14: =IF($B14="","",$C$1-3*$C$2) -> -0.99807083 | L14: =IF($B14="","",$C$1-2*$C$2) -> -0.65002968 | M14: =IF($B14="","",$C$1-$C$2) -> -0.30198852 | N14: =IF($B14="","",$C$1) -> 0.046052632 | O14: =IF($B14="","",$C$1+1*$C$2) -> 0.39409379 | P14: =IF($B14="","",$C$1+2*$C$2) -> 0.74213494 | Q14: =IF($B14="","",$C$1+3*$C$2) -> 1.0901761
A15: 44986 | B15: =IF('Catalogo de Variaveis'!G20="","",SUM('Catalogo de Variaveis'!G17:G20)) -> 2 | C15: =IFERROR(IF($B15="","",AVERAGE('Catalogo de Variaveis'!G20-'Catalogo de Variaveis'!G19,'Catalogo de Variaveis'!G19-'Catalogo de Variaveis'!G18,'Catalogo de Variaveis'!G18-'Catalogo de Variaveis'!G17,'Catalogo de Variaveis'!G17-'Catalogo de Variaveis'!G16)),0) -> 0 | D15: =IF($B15="","",IF(OR($J$1="",$J$2=""),$B$1-3*$B$2,$J$1-3*$J$2)) -> -3.4730071 | E15: =IF($B15="","",IF(OR($J$1="",$J$2=""),$B$1-2*$B$2,$J$1-2*$J$2)) -> -1.0083205 | F15: =IF($B15="","",IF(OR($J$1="",$J$2=""),$B$1-$B$2,$J$1-$J$2)) -> 1.4563661 | G15: =IF($B15="","",IF(OR($J$1="",$J$2=""),$B$1,$J$1)) -> 3.9210526 | H15: =IF($B15="","",IF(OR($J$1="",$J$2=""),$B$1+$B$2,$J$1+$J$2)) -> 6.3857392 | I15: =IF($B15="","",IF(OR($J$1="",$J$2=""),$B$1+2*$B$2,$J$1+2*$J$2)) -> 8.8504258 | J15: =IF($B15="","",IF(OR($J$1="",$J$2=""),$B$1+3*$B$2,$J$1+3*$J$2)) -> 11.315112 | K15: =IF($B15="","",$C$1-3*$C$2) -> -0.99807083 | L15: =IF($B15="","",$C$1-2*$C$2) -> -0.65002968 | M15: =IF($B15="","",$C$1-$C$2) -> -0.30198852 | N15: =IF($B15="","",$C$1) -> 0.046052632 | O15: =IF($B15="","",$C$1+1*$C$2) -> 0.39409379 | P15: =IF($B15="","",$C$1+2*$C$2) -> 0.74213494 | Q15: =IF($B15="","",$C$1+3*$C$2) -> 1.0901761
A16: 45017 | B16: =IF('Catalogo de Variaveis'!G21="","",SUM('Catalogo de Variaveis'!G18:G21)) -> 2 | C16: =IFERROR(IF($B16="","",AVERAGE('Catalogo de Variaveis'!G21-'Catalogo de Variaveis'!G20,'Catalogo de Variaveis'!G20-'Catalogo de Variaveis'!G19,'Catalogo de Variaveis'!G19-'Catalogo de Variaveis'!G18,'Catalogo de Variaveis'!G18-'Catalogo de Variaveis'!G17)),0) -> 0 | D16: =IF($B16="","",IF(OR($J$1="",$J$2=""),$B$1-3*$B$2,$J$1-3*$J$2)) -> -3.4730071 | E16: =IF($B16="","",IF(OR($J$1="",$J$2=""),$B$1-2*$B$2,$J$1-2*$J$2)) -> -1.0083205 | F16: =IF($B16="","",IF(OR($J$1="",$J$2=""),$B$1-$B$2,$J$1-$J$2)) -> 1.4563661 | G16: =IF($B16="","",IF(OR($J$1="",$J$2=""),$B$1,$J$1)) -> 3.9210526 | H16: =IF($B16="","",IF(OR($J$1="",$J$2=""),$B$1+$B$2,$J$1+$J$2)) -> 6.3857392 | I16: =IF($B16="","",IF(OR($J$1="",$J$2=""),$B$1+2*$B$2,$J$1+2*$J$2)) -> 8.8504258 | J16: =IF($B16="","",IF(OR($J$1="",$J$2=""),$B$1+3*$B$2,$J$1+3*$J$2)) -> 11.315112 | K16: =IF($B16="","",$C$1-3*$C$2) -> -0.99807083 | L16: =IF($B16="","",$C$1-2*$C$2) -> -0.65002968 | M16: =IF($B16="","",$C$1-$C$2) -> -0.30198852 | N16: =IF($B16="","",$C$1) -> 0.046052632 | O16: =IF($B16="","",$C$1+1*$C$2) -> 0.39409379 | P16: =IF($B16="","",$C$1+2*$C$2) -> 0.74213494 | Q16: =IF($B16="","",$C$1+3*$C$2) -> 1.0901761
A17: 45047 | B17: =IF('Catalogo de Variaveis'!G22="","",SUM('Catalogo de Variaveis'!G19:G22)) -> 2 | C17: =IFERROR(IF($B17="","",AVERAGE('Catalogo de Variaveis'!G22-'Catalogo de Variaveis'!G21,'Catalogo de Variaveis'!G21-'Catalogo de Variaveis'!G20,'Catalogo de Variaveis'!G20-'Catalogo de Variaveis'!G19,'Catalogo de Variaveis'!G19-'Catalogo de Variaveis'!G18)),0) -> 0 | D17: =IF($B17="","",IF(OR($J$1="",$J$2=""),$B$1-3*$B$2,$J$1-3*$J$2)) -> -3.4730071 | E17: =IF($B17="","",IF(OR($J$1="",$J$2=""),$B$1-2*$B$2,$J$1-2*$J$2)) -> -1.0083205 | F17: =IF($B17="","",IF(OR($J$1="",$J$2=""),$B$1-$B$2,$J$1-$J$2)) -> 1.4563661 | G17: =IF($B17="","",IF(OR($J$1="",$J$2=""),$B$1,$J$1)) -> 3.9210526 | H17: =IF($B17="","",IF(OR($J$1="",$J$2=""),$B$1+$B$2,$J$1+$J$2)) -> 6.3857392 | I17: =IF($B17="","",IF(OR($J$1="",$J$2=""),$B$1+2*$B$2,$J$1+2*$J$2)) -> 8.8504258 | J17: =IF($B17="","",IF(OR($J$1="",$J$2=""),$B$1+3*$B$2,$J$1+3*$J$2)) -> 11.315112 | K17: =IF($B17="","",$C$1-3*$C$2) -> -0.99807083 | L17: =IF($B17="","",$C$1-2*$C$2) -> -0.65002968 | M17: =IF($B17="","",$C$1-$C$2) -> -0.30198852 | N17: =IF($B17="","",$C$1) -> 0.046052632 | O17: =IF($B17="","",$C$1+1*$C$2) -> 0.39409379 | P17: =IF($B17="","",$C$1+2*$C$2) -> 0.74213494 | Q17: =IF($B17="","",$C$1+3*$C$2) -> 1.0901761
A18: 45078 | B18: =IF('Catalogo de Variaveis'!G23="","",SUM('Catalogo de Variaveis'!G20:G23)) -> 1 | C18: =IFERROR(IF($B18="","",AVERAGE('Catalogo de Variaveis'!G23-'Catalogo de Variaveis'!G22,'Catalogo de Variaveis'!G22-'Catalogo de Variaveis'!G21,'Catalogo de Variaveis'!G21-'Catalogo de Variaveis'!G20,'Catalogo de Variaveis'!G20-'Catalogo de Variaveis'!G19)),0) -> -0.25 | D18: =IF($B18="","",IF(OR($J$1="",$J$2=""),$B$1-3*$B$2,$J$1-3*$J$2)) -> -3.4730071 | E18: =IF($B18="","",IF(OR($J$1="",$J$2=""),$B$1-2*$B$2,$J$1-2*$J$2)) -> -1.0083205 | F18: =IF($B18="","",IF(OR($J$1="",$J$2=""),$B$1-$B$2,$J$1-$J$2)) -> 1.4563661 | G18: =IF($B18="","",IF(OR($J$1="",$J$2=""),$B$1,$J$1)) -> 3.9210526 | H18: =IF($B18="","",IF(OR($J$1="",$J$2=""),$B$1+$B$2,$J$1+$J$2)) -> 6.3857392 | I18: =IF($B18="","",IF(OR($J$1="",$J$2=""),$B$1+2*$B$2,$J$1+2*$J$2)) -> 8.8504258 | J18: =IF($B18="","",IF(OR($J$1="",$J$2=""),$B$1+3*$B$2,$J$1+3*$J$2)) -> 11.315112 | K18: =IF($B18="","",$C$1-3*$C$2) -> -0.99807083 | L18: =IF($B18="","",$C$1-2*$C$2) -> -0.65002968 | M18: =IF($B18="","",$C$1-$C$2) -> -0.30198852 | N18: =IF($B18="","",$C$1) -> 0.046052632 | O18: =IF($B18="","",$C$1+1*$C$2) -> 0.39409379 | P18: =IF($B18="","",$C$1+2*$C$2) -> 0.74213494 | Q18: =IF($B18="","",$C$1+3*$C$2) -> 1.0901761
A19: 45108 | B19: =IF('Catalogo de Variaveis'!G24="","",SUM('Catalogo de Variaveis'!G21:G24)) -> 3 | C19: =IFERROR(IF($B19="","",AVERAGE('Catalogo de Variaveis'!G24-'Catalogo de Variaveis'!G23,'Catalogo de Variaveis'!G23-'Catalogo de Variaveis'!G22,'Catalogo de Variaveis'!G22-'Catalogo de Variaveis'!G21,'Catalogo de Variaveis'!G21-'Catalogo de Variaveis'!G20)),0) -> 0.5 | D19: =IF($B19="","",IF(OR($J$1="",$J$2=""),$B$1-3*$B$2,$J$1-3*$J$2)) -> -3.4730071 | E19: =IF($B19="","",IF(OR($J$1="",$J$2=""),$B$1-2*$B$2,$J$1-2*$J$2)) -> -1.0083205 | F19: =IF($B19="","",IF(OR($J$1="",$J$2=""),$B$1-$B$2,$J$1-$J$2)) -> 1.4563661 | G19: =IF($B19="","",IF(OR($J$1="",$J$2=""),$B$1,$J$1)) -> 3.9210526 | H19: =IF($B19="","",IF(OR($J$1="",$J$2=""),$B$1+$B$2,$J$1+$J$2)) -> 6.3857392 | I19: =IF($B19="","",IF(OR($J$1="",$J$2=""),$B$1+2*$B$2,$J$1+2*$J$2)) -> 8.8504258 | J19: =IF($B19="","",IF(OR($J$1="",$J$2=""),$B$1+3*$B$2,$J$1+3*$J$2)) -> 11.315112 | K19: =IF($B19="","",$C$1-3*$C$2) -> -0.99807083 | L19: =IF($B19="","",$C$1-2*$C$2) -> -0.65002968 | M19: =IF($B19="","",$C$1-$C$2) -> -0.30198852 | N19: =IF($B19="","",$C$1) -> 0.046052632 | O19: =IF($B19="","",$C$1+1*$C$2) -> 0.39409379 | P19: =IF($B19="","",$C$1+2*$C$2) -> 0.74213494 | Q19: =IF($B19="","",$C$1+3*$C$2) -> 1.0901761
A20: 45139 | B20: =IF('Catalogo de Variaveis'!G25="","",SUM('Catalogo de Variaveis'!G22:G25)) -> 5 | C20: =IFERROR(IF($B20="","",AVERAGE('Catalogo de Variaveis'!G25-'Catalogo de Variaveis'!G24,'Catalogo de Variaveis'!G24-'Catalogo de Variaveis'!G23,'Catalogo de Variaveis'!G23-'Catalogo de Variaveis'!G22,'Catalogo de Variaveis'!G22-'Catalogo de Variaveis'!G21)),0) -> 0.5 | D20: =IF($B20="","",IF(OR($J$1="",$J$2=""),$B$1-3*$B$2,$J$1-3*$J$2)) -> -3.4730071 | E20: =IF($B20="","",IF(OR($J$1="",$J$2=""),$B$1-2*$B$2,$J$1-2*$J$2)) -> -1.0083205 | F20: =IF($B20="","",IF(OR($J$1="",$J$2=""),$B$1-$B$2,$J$1-$J$2)) -> 1.4563661 | G20: =IF($B20="","",IF(OR($J$1="",$J$2=""),$B$1,$J$1)) -> 3.9210526 | H20: =IF($B20="","",IF(OR($J$1="",$J$2=""),$B$1+$B$2,$J$1+$J$2)) -> 6.3857392 | I20: =IF($B20="","",IF(OR($J$1="",$J$2=""),$B$1+2*$B$2,$J$1+2*$J$2)) -> 8.8504258 | J20: =IF($B20="","",IF(OR($J$1="",$J$2=""),$B$1+3*$B$2,$J$1+3*$J$2)) -> 11.315112 | K20: =IF($B20="","",$C$1-3*$C$2) -> -0.99807083 | L20: =IF($B20="","",$C$1-2*$C$2) -> -0.65002968 | M20: =IF($B20="","",$C$1-$C$2) -> -0.30198852 | N20: =IF($B20="","",$C$1) -> 0.046052632 | O20: =IF($B20="","",$C$1+1*$C$2) -> 0.39409379 | P20: =IF($B20="","",$C$1+2*$C$2) -> 0.74213494 | Q20: =IF($B20="","",$C$1+3*$C$2) -> 1.0901761
... A96: 47453 | B96: =IF('Catalogo de Variaveis'!G101="","",SUM('Catalogo de Variaveis'!G98:G101)) | C96: =IFERROR(IF($B96="","",AVERAGE('Catalogo de Variaveis'!G101-'Catalogo de Variaveis'!G100,'Catalogo de Variaveis'!G100-'Catalogo de Variaveis'!G99,'Catalogo de Variaveis'!G99-'Catalogo de Variaveis'!G98,'Catalogo de Variaveis'!G98-'Catalogo de Variaveis'!G97)),0) | D96: =IF($B96="","",IF(OR($J$1="",$J$2=""),$B$1-3*$B$2,$J$1-3*$J$2)) | E96: =IF($B96="","",IF(OR($J$1="",$J$2=""),$B$1-2*$B$2,$J$1-2*$J$2)) | F96: =IF($B96="","",IF(OR($J$1="",$J$2=""),$B$1-$B$2,$J$1-$J$2)) | G96: =IF($B96="","",IF(OR($J$1="",$J$2=""),$B$1,$J$1)) | H96: =IF($B96="","",IF(OR($J$1="",$J$2=""),$B$1+$B$2,$J$1+$J$2)) | I96: =IF($B96="","",IF(OR($J$1="",$J$2=""),$B$1+2*$B$2,$J$1+2*$J$2)) | J96: =IF($B96="","",IF(OR($J$1="",$J$2=""),$B$1+3*$B$2,$J$1+3*$J$2)) | K96: =IF($B96="","",$C$1-3*$C$2) | L96: =IF($B96="","",$C$1-2*$C$2) | M96: =IF($B96="","",$C$1-$C$2) | N96: =IF($B96="","",$C$1) | O96: =IF($B96="","",$C$1+1*$C$2) | P96: =IF($B96="","",$C$1+2*$C$2) | Q96: =IF($B96="","",$C$1+3*$C$2)

Sheet V02
A1: Média | B1: =AVERAGE(B9:B1048576) -> 57.631579 | C1: =AVERAGE(C9:C1048576) -> 0.42105263 | I1: LME | J1: =IF(LME="","",LME)
A2: Desvio Padrão | B2: =_xlfn.STDEV.S(B9:B1048576) -> 18.623468 | C2: =_xlfn.STDEV.S(C9:C1048576) -> 2.4646866 | I2: VME | J2: =IF(VME="","",VME/3)
A3: Máximo | B3: =MAX(B9:B1048576) -> 103 | C3: =MAX(C9:C1048576) -> 4.25
A4: Mínimo | B4: =MIN(B9:B1048576) -> 16 | C4: =MIN(C9:C1048576) -> -6
A5: V02 - NÚMERO TOTAL DE DENÚNCIAS NO PERÍODO DE REFERÊNCIA RECEBIDAS PELOS DIVERSOS CANAIS DE DENÚNCIAS DA COMPANHIA
A7: DADOS | D7: SOMA | K7: AMPLITUDE
A8: Período | B8: Soma | C8: Amplitude | D8: LIC | E8: L2I | F8: L1I | G8: LMC | H8: L1S | I8: L2S | J8: LSC | K8: LIC | L8: L2I | M8: L1I | N8: LMC | O8: L1S | P8: L2S | Q8: LSC
A9: 44805 | B9: =IF('Catalogo de Variaveis'!H14="","",SUM('Catalogo de Variaveis'!H11:H14)) -> 16 | C9: =IFERROR(IF($B9="","",AVERAGE('Catalogo de Variaveis'!H14-'Catalogo de Variaveis'!H13,'Catalogo de Variaveis'!H13-'Catalogo de Variaveis'!H12,'Catalogo de Variaveis'!H12-'Catalogo de Variaveis'!H11,'Catalogo de Variaveis'!H11-'Catalogo de Variaveis'!H10)),0) -> 4 | D9: =IF($B9="","",IF(OR($J$1="",$J$2=""),$B$1-3*$B$2,$J$1-3*$J$2)) -> 1.7611741 | E9: =IF($B9="","",IF(OR($J$1="",$J$2=""),$B$1-2*$B$2,$J$1-2*$J$2)) -> 20.384642 | F9: =IF($B9="","",IF(OR($J$1="",$J$2=""),$B$1-$B$2,$J$1-$J$2)) -> 39.008111 | G9: =IF($B9="","",IF(OR($J$1="",$J$2=""),$B$1,$J$1)) -> 57.631579 | H9: =IF($B9="","",IF(OR($J$1="",$J$2=""),$B$1+$B$2,$J$1+$J$2)) -> 76.255047 | I9: =IF($B9="","",IF(OR($J$1="",$J$2=""),$B$1+2*$B$2,$J$1+2*$J$2)) -> 94.878515 | J9: =IF($B9="","",IF(OR($J$1="",$J$2=""),$B$1+3*$B$2,$J$1+3*$J$2)) -> 113.50198 | K9: =IF($B9="","",$C$1-3*$C$2) -> -6.9730071 | L9: =IF($B9="","",$C$1-2*$C$2) -> -4.5083205 | M9: =IF($B9="","",$C$1-$C$2) -> -2.0436339 | N9: =IF($B9="","",$C$1) -> 0.42105263 | O9: =IF($B9="","",$C$1+1*$C$2) -> 2.8857392 | P9: =IF($B9="","",$C$1+2*$C$2) -> 5.3504258 | Q9: =IF($B9="","",$C$1+3*$C$2) -> 7.8151124
A10: 44835 | B10: =IF('Catalogo de Variaveis'!H15="","",SUM('Catalogo de Variaveis'!H12:H15)) -> 29 | C10: =IFERROR(IF($B10="","",AVERAGE('Catalogo de Variaveis'!H15-'Catalogo de Variaveis'!H14,'Catalogo de Variaveis'!H14-'Catalogo de Variaveis'!H13,'Catalogo de Variaveis'!H13-'Catalogo de Variaveis'!H12,'Catalogo de Variaveis'!H12-'Catalogo de Variaveis'!H11)),0) -> 3.25 | D10: =IF($B10="","",IF(OR($J$1="",$J$2=""),$B$1-3*$B$2,$J$1-3*$J$2)) -> 1.7611741 | E10: =IF($B10="","",IF(OR($J$1="",$J$2=""),$B$1-2*$B$2,$J$1-2*$J$2)) -> 20.384642 | F10: =IF($B10="","",IF(OR($J$1="",$J$2=""),$B$1-$B$2,$J$1-$J$2)) -> 39.008111 | G10: =IF($B10="","",IF(OR($J$1="",$J$2=""),$B$1,$J$1)) -> 57.631579 | H10: =IF($B10="","",IF(OR($J$1="",$J$2=""),$B$1+$B$2,$J$1+$J$2)) -> 76.255047 | I10: =IF($B10="","",IF(OR($J$1="",$J$2=""),$B$1+2*$B$2,$J$1+2*$J$2)) -> 94.878515 | J10: =IF($B10="","",IF(OR($J$1="",$J$2=""),$B$1+3*$B$2,$J$1+3*$J$2)) -> 113.50198 | K10: =IF($B10="","",$C$1-3*$C$2) -> -6.9730071 | L10: =IF($B10="","",$C$1-2*$C$2) -> -4.5083205 | M10: =IF($B10="","",$C$1-$C$2) -> -2.0436339 | N10: =IF($B10="","",$C$1) -> 0.42105263 | O10: =IF($B10="","",$C$1+1*$C$2) -> 2.8857392 | P10: =IF($B10="","",$C$1+2*$C$2) -> 5.3504258 | Q10: =IF($B10="","",$C$1+3*$C$2) -> 7.8151124
A11: 44866 | B11: =IF('Catalogo de Variaveis'!H16="","",SUM('Catalogo de Variaveis'!H13:H16)) -> 38 | C11: =IFERROR(IF($B11="","",AVERAGE('Catalogo de Variaveis'!H16-'Catalogo de Variaveis'!H15,'Catalogo de Variaveis'!H15-'Catalogo de Variaveis'!H14,'Catalogo de Variaveis'!H14-'Catalogo de Variaveis'!H13,'Catalogo de Variaveis'!H13-'Catalogo de Variaveis'!H12)),0) -> 2.25 | D11: =IF($B11="","",IF(OR($J$1="",$J$2=""),$B$1-3*$B$2,$J$1-3*$J$2)) -> 1.7611741 | E11: =IF($B11="","",IF(OR($J$1="",$J$2=""),$B$1-2*$B$2,$J$1-2*$J$2)) -> 20.384642 | F11: =IF($B11="","",IF(OR($J$1="",$J$2=""),$B$1-$B$2,$J$1-$J$2)) -> 39.008111 | G11: =IF($B11="","",IF(OR($J$1="",$J$2=""),$B$1,$J$1)) -> 57.631579 | H11: =IF($B11="","",IF(OR($J$1="",$J$2=""),$B$1+$B$2,$J$1+$J$2)) -> 76.255047 | I11: =IF($B11="","",IF(OR($J$1="",$J$2=""),$B$1+2*$B$2,$J$1+2*$J$2)) -> 94.878515 | J11: =IF($B11="","",IF(OR($J$1="",$J$2=""),$B$1+3*$B$2,$J$1+3*$J$2)) -> 113.50198 | K11: =IF($B11="","",$C$1-3*$C$2) -> -6.9730071 | L11: =IF($B11="","",$C$1-2*$C$2) -> -4.5083205 | M11: =IF($B11="","",$C$1-$C$2) -> -2.0436339 | N11: =IF($B11="","",$C$1) -> 0.42105263 | O11: =IF($B11="","",$C$1+1*$C$2) -> 2.8857392 | P11: =IF($B11="","",$C$1+2*$C$2) -> 5.3504258 | Q11: =IF($B11="","",$C$1+3*$C$2) -> 7.8151124
A12: 44896 | B12: =IF('Catalogo de Variaveis'!H17="","",SUM('Catalogo de Variaveis'!H14:H17)) -> 45 | C12: =IFERROR(IF($B12="","",AVERAGE('Catalogo de Variaveis'!H17-'Catalogo de Variaveis'!H16,'Catalogo de Variaveis'!H16-'Catalogo de Variaveis'!H15,'Catalogo de Variaveis'!H15-'Catalogo de Variaveis'!H14,'Catalogo de Variaveis'!H14-'Catalogo de Variaveis'!H13)),0) -> 1.75 | D12: =IF($B12="","",IF(OR($J$1="",$J$2=""),$B$1-3*$B$2,$J$1-3*$J$2)) -> 1.7611741 | E12: =IF($B12="","",IF(OR($J$1="",$J$2=""),$B$1-2*$B$2,$J$1-2*$J$2)) -> 20.384642 | F12: =IF($B12="","",IF(OR($J$1="",$J$2=""),$B$1-$B$2,$J$1-$J$2)) -> 39.008111 | G12: =IF($B12="","",IF(OR($J$1="",$J$2=""),$B$1,$J$1)) -> 57.631579 | H12: =IF($B12="","",IF(OR($J$1="",$J$2=""),$B$1+$B$2,$J$1+$J$2)) -> 76.255047 | I12: =IF($B12="","",IF(OR($J$1="",$J$2=""),$B$1+2*$B$2,$J$1+2*$J$2)) -> 94.878515 | J12: =IF($B12="","",IF(OR($J$1="",$J$2=""),$B$1+3*$B$2,$J$1+3*$J$2)) -> 113.50198 | K12: =IF($B12="","",$C$1-3*$C$2) -> -6.9730071 | L12: =IF($B12="","",$C$1-2*$C$2) -> -4.5083205 | M12: =IF($B12="","",$C$1-$C$2) -> -2.0436339 | N12: =IF($B12="","",$C$1) -> 0.42105263 | O12: =IF($B12="","",$C$1+1*$C$2) -> 2.8857392 | P12: =IF($B12="","",$C$1+2*$C$2) -> 5.3504258 | Q12: =IF($B12="","",$C$1+3*$C$2) -> 7.8151124
A13: 44927 | B13: =IF('Catalogo de Variaveis'!H18="","",SUM('Catalogo de Variaveis'!H15:H18)) -> 35 | C13: =IFERROR(IF($B13="","",AVERAGE('Catalogo de Variaveis'!H18-'Catalogo de Variaveis'!H17,'Catalogo de Variaveis'!H17-'Catalogo de Variaveis'!H16,'Catalogo de Variaveis'!H16-'Catalogo de Variaveis'!H15,'Catalogo de Variaveis'!H15-'Catalogo de Variaveis'!H14)),0) -> -2.5 | D13: =IF($B13="","",IF(OR($J$1="",$J$2=""),$B$1-3*$B$2,$J$1-3*$J$2)) -> 1.7611741 | E13: =IF($B13="","",IF(OR($J$1="",$J$2=""),$B$1-2*$B$2,$J$1-2*$J$2)) -> 20.384642 | F13: =IF($B13="","",IF(OR($J$1="",$J$2=""),$B$1-$B$2,$J$1-$J$2)) -> 39.008111 | G13: =IF($B13="","",IF(OR($J$1="",$J$2=""),$B$1,$J$1)) -> 57.631579 | H13: =IF($B13="","",IF(OR($J$1="",$J$2=""),$B$1+$B$2,$J$1+$J$2)) -> 76.255047 | I13: =IF($B13="","",IF(OR($J$1="",$J$2=""),$B$1+2*$B$2,$J$1+2*$J$2)) -> 94.878515 | J13: =IF($B13="","",IF(OR($J$1="",$J$2=""),$B$1+3*$B$2,$J$1+3*$J$2)) -> 113.50198 | K13: =IF($B13="","",$C$1-3*$C$2) -> -6.9730071 | L13: =IF($B13="","",$C$1-2*$C$2) -> -4.5083205 | M13: =IF($B13="","",$C$1-$C$2) -> -2.0436339 | N13: =IF($B13="","",$C$1) -> 0.42105263 | O13: =IF($B13="","",$C$1+1*$C$2) -> 2.8857392 | P13: =IF($B13="","",$C$1+2*$C$2) -> 5.3504258 | Q13: =IF($B13="","",$C$1+3*$C$2) -> 7.8151124
A14: 44958 | B14: =IF('Catalogo de Variaveis'!H19="","",SUM('Catalogo de Variaveis'!H16:H19)) -> 36 | C14: =IFERROR(IF($B14="","",AVERAGE('Catalogo de Variaveis'!H19-'Catalogo de Variaveis'!H18,'Catalogo de Variaveis'!H18-'Catalogo de Variaveis'!H17,'Catalogo de Variaveis'!H17-'Catalogo de Variaveis'!H16,'Catalogo de Variaveis'!H16-'Catalogo de Variaveis'!H15)),0) -> 0.25 | D14: =IF($B14="","",IF(OR($J$1="",$J$2=""),$B$1-3*$B$2,$J$1-3*$J$2)) -> 1.7611741 | E14: =IF($B14="","",IF(OR($J$1="",$J$2=""),$B$1-2*$B$2,$J$1-2*$J$2)) -> 20.384642 | F14: =IF($B14="","",IF(OR($J$1="",$J$2=""),$B$1-$B$2,$J$1-$J$2)) -> 39.008111 | G14: =IF($B14="","",IF(OR($J$1="",$J$2=""),$B$1,$J$1)) -> 57.631579 | H14: =IF($B14="","",IF(OR($J$1="",$J$2=""),$B$1+$B$2,$J$1+$J$2)) -> 76.255047 | I14: =IF($B14="","",IF(OR($J$1="",$J$2=""),$B$1+2*$B$2,$J$1+2*$J$2)) -> 94.878515 | J14: =IF($B14="","",IF(OR($J$1="",$J$2=""),$B$1+3*$B$2,$J$1+3*$J$2)) -> 113.50198 | K14: =IF($B14="","",$C$1-3*$C$2) -> -6.9730071 | L14: =IF($B14="","",$C$1-2*$C$2) -> -4.5083205 | M14: =IF($B14="","",$C$1-$C$2) -> -2.0436339 | N14: =IF($B14="","",$C$1) -> 0.42105263 | O14: =IF($B14="","",$C$1+1*$C$2) -> 2.8857392 | P14: =IF($B14="","",$C$1+2*$C$2) -> 5.3504258 | Q14: =IF($B14="","",$C$1+3*$C$2) -> 7.8151124
A15: 44986 | B15: =IF('Catalogo de Variaveis'!H20="","",SUM('Catalogo de Variaveis'!H17:H20)) -> 38 | C15: =IFERROR(IF($B15="","",AVERAGE('Catalogo de Variaveis'!H20-'Catalogo de Variaveis'!H19,'Catalogo de Variaveis'!H19-'Catalogo de Variaveis'!H18,'Catalogo de Variaveis'!H18-'Catalogo de Variaveis'!H17,'Catalogo de Variaveis'!H17-'Catalogo de Variaveis'!H16)),0) -> 0.5 | D15: =IF($B15="","",IF(OR($J$1="",$J$2=""),$B$1-3*$B$2,$J$1-3*$J$2)) -> 1.7611741 | E15: =IF($B15="","",IF(OR($J$1="",$J$2=""),$B$1-2*$B$2,$J$1-2*$J$2)) -> 20.384642 | F15: =IF($B15="","",IF(OR($J$1="",$J$2=""),$B$1-$B$2,$J$1-$J$2)) -> 39.008111 | G15: =IF($B15="","",IF(OR($J$1="",$J$2=""),$B$1,$J$1)) -> 57.631579 | H15: =IF($B15="","",IF(OR($J$1="",$J$2=""),$B$1+$B$2,$J$1+$J$2)) -> 76.255047 | I15: =IF($B15="","",IF(OR($J$1="",$J$2=""),$B$1+2*$B$2,$J$1+2*$J$2)) -> 94.878515 | J15: =IF($B15="","",IF(OR($J$1="",$J$2=""),$B$1+3*$B$2,$J$1+3*$J$2)) -> 113.50198 | K15: =IF($B15="","",$C$1-3*$C$2) -> -6.9730071 | L15: =IF($B15="","",$C$1-2*$C$2) -> -4.5083205 | M15: =IF($B15="","",$C$1-$C$2) -> -2.0436339 | N15: =IF($B15="","",$C$1) -> 0.42105263 | O15: =IF($B15="","",$C$1+1*$C$2) -> 2.8857392 | P15: =IF($B15="","",$C$1+2*$C$2) -> 5.3504258 | Q15: =IF($B15="","",$C$1+3*$C$2) -> 7.8151124
A16: 45017 | B16: =IF('Catalogo de Variaveis'!H21="","",SUM('Catalogo de Variaveis'!H18:H21)) -> 43 | C16: =IFERROR(IF($B16="","",AVERAGE('Catalogo de Variaveis'!H21-'Catalogo de Variaveis'!H20,'Catalogo de Variaveis'!H20-'Catalogo de Variaveis'!H19,'Catalogo de Variaveis'!H19-'Catalogo de Variaveis'!H18,'Catalogo de Variaveis'!H18-'Catalogo de Variaveis'!H17)),0) -> 1.25 | D16: =IF($B16="","",IF(OR($J$1="",$J$2=""),$B$1-3*$B$2,$J$1-3*$J$2)) -> 1.7611741 | E16: =IF($B16="","",IF(OR($J$1="",$J$2=""),$B$1-2*$B$2,$J$1-2*$J$2)) -> 20.384642 | F16: =IF($B16="","",IF(OR($J$1="",$J$2=""),$B$1-$B$2,$J$1-$J$2)) -> 39.008111 | G16: =IF($B16="","",IF(OR($J$1="",$J$2=""),$B$1,$J$1)) -> 57.631579 | H16: =IF($B16="","",IF(OR($J$1="",$J$2=""),$B$1+$B$2,$J$1+$J$2)) -> 76.255047 | I16: =IF($B16="","",IF(OR($J$1="",$J$2=""),$B$1+2*$B$2,$J$1+2*$J$2)) -> 94.878515 | J16: =IF($B16="","",IF(OR($J$1="",$J$2=""),$B$1+3*$B$2,$J$1+3*$J$2)) -> 113.50198 | K16: =IF($B16="","",$C$1-3*$C$2) -> -6.9730071 | L16: =IF($B16="","",$C$1-2*$C$2) -> -4.5083205 | M16: =IF($B16="","",$C$1-$C$2) -> -2.0436339 | N16: =IF($B16="","",$C$1) -> 0.42105263 | O16: =IF($B16="","",$C$1+1*$C$2) -> 2.8857392 | P16: =IF($B16="","",$C$1+2*$C$2) -> 5.3504258 | Q16: =IF($B16="","",$C$1+3*$C$2) -> 7.8151124
A17: 45047 | B17: =IF('Catalogo de Variaveis'!H22="","",SUM('Catalogo de Variaveis'!H19:H22)) -> 52 | C17: =IFERROR(IF($B17="","",AVERAGE('Catalogo de Variaveis'!H22-'Catalogo de Variaveis'!H21,'Catalogo de Variaveis'!H21-'Catalogo de Variaveis'!H20,'Catalogo de Variaveis'!H20-'Catalogo de Variaveis'!H19,'Catalogo de Variaveis'!H19-'Catalogo de Variaveis'!H18)),0) -> 2.25 | D17: =IF($B17="","",IF(OR($J$1="",$J$2=""),$B$1-3*$B$2,$J$1-3*$J$2)) -> 1.7611741 | E17: =IF($B17="","",IF(OR($J$1="",$J$2=""),$B$1-2*$B$2,$J$1-2*$J$2)) -> 20.384642 | F17: =IF($B17="","",IF(OR($J$1="",$J$2=""),$B$1-$B$2,$J$1-$J$2)) -> 39.008111 | G17: =IF($B17="","",IF(OR($J$1="",$J$2=""),$B$1,$J$1)) -> 57.631579 | H17: =IF($B17="","",IF(OR($J$1="",$J$2=""),$B$1+$B$2,$J$1+$J$2)) -> 76.255047 | I17: =IF($B17="","",IF(OR($J$1="",$J$2=""),$B$1+2*$B$2,$J$1+2*$J$2)) -> 94.878515 | J17: =IF($B17="","",IF(OR($J$1="",$J$2=""),$B$1+3*$B$2,$J$1+3*$J$2)) -> 113.50198 | K17: =IF($B17="","",$C$1-3*$C$2) -> -6.9730071 | L17: =IF($B17="","",$C$1-2*$C$2) -> -4.5083205 | M17: =IF($B17="","",$C$1-$C$2) -> -2.0436339 | N17: =IF($B17="","",$C$1) -> 0.42105263 | O17: =IF($B17="","",$C$1+1*$C$2) -> 2.8857392 | P17: =IF($B17="","",$C$1+2*$C$2) -> 5.3504258 | Q17: =IF($B17="","",$C$1+3*$C$2) -> 7.8151124
A18: 45078 | B18: =IF('Catalogo de Variaveis'!H23="","",SUM('Catalogo de Variaveis'!H20:H23)) -> 47 | C18: =IFERROR(IF($B18="","",AVERAGE('Catalogo de Variaveis'!H23-'Catalogo de Variaveis'!H22,'Catalogo de Variaveis'!H22-'Catalogo de Variaveis'!H21,'Catalogo de Variaveis'!H21-'Catalogo de Variaveis'!H20,'Catalogo de Variaveis'!H20-'Catalogo de Variaveis'!H19)),0) -> -1.25 | D18: =IF($B18="","",IF(OR($J$1="",$J$2=""),$B$1-3*$B$2,$J$1-3*$J$2)) -> 1.7611741 | E18: =IF($B18="","",IF(OR($J$1="",$J$2=""),$B$1-2*$B$2,$J$1-2*$J$2)) -> 20.384642 | F18: =IF($B18="","",IF(OR($J$1="",$J$2=""),$B$1-$B$2,$J$1-$J$2)) -> 39.008111 | G18: =IF($B18="","",IF(OR($J$1="",$J$2=""),$B$1,$J$1)) -> 57.631579 | H18: =IF($B18="","",IF(OR($J$1="",$J$2=""),$B$1+$B$2,$J$1+$J$2)) -> 76.255047 | I18: =IF($B18="","",IF(OR($J$1="",$J$2=""),$B$1+2*$B$2,$J$1+2*$J$2)) -> 94.878515 | J18: =IF($B18="","",IF(OR($J$1="",$J$2=""),$B$1+3*$B$2,$J$1+3*$J$2)) -> 113.50198 | K18: =IF($B18="","",$C$1-3*$C$2) -> -6.9730071 | L18: =IF($B18="","",$C$1-2*$C$2) -> -4.5083205 | M18: =IF($B18="","",$C$1-$C$2) -> -2.0436339 | N18: =IF($B18="","",$C$1) -> 0.42105263 | O18: =IF($B18="","",$C$1+1*$C$2) -> 2.8857392 | P18: =IF($B18="","",$C$1+2*$C$2) -> 5.3504258 | Q18: =IF($B18="","",$C$1+3*$C$2) -> 7.8151124
A19: 45108 | B19: =IF('Catalogo de Variaveis'!H24="","",SUM('Catalogo de Variaveis'!H21:H24)) -> 52 | C19: =IFERROR(IF($B19="","",AVERAGE('Catalogo de Variaveis'!H24-'Catalogo de Variaveis'!H23,'Catalogo de Variaveis'!H23-'Catalogo de Variaveis'!H22,'Catalogo de Variaveis'!H22-'Catalogo de Variaveis'!H21,'Catalogo de Variaveis'!H21-'Catalogo de Variaveis'!H20)),0) -> 1.25 | D19: =IF($B19="","",IF(OR($J$1="",$J$2=""),$B$1-3*$B$2,$J$1-3*$J$2)) -> 1.7611741 | E19: =IF($B19="","",IF(OR($J$1="",$J$2=""),$B$1-2*$B$2,$J$1-2*$J$2)) -> 20.384642 | F19: =IF($B19="","",IF(OR($J$1="",$J$2=""),$B$1-$B$2,$J$1-$J$2)) -> 39.008111 | G19: =IF($B19="","",IF(OR($J$1="",$J$2=""),$B$1,$J$1)) -> 57.631579 | H19: =IF($B19="","",IF(OR($J$1="",$J$2=""),$B$1+$B$2,$J$1+$J$2)) -> 76.255047 | I19: =IF($B19="","",IF(OR($J$1="",$J$2=""),$B$1+2*$B$2,$J$1+2*$J$2)) -> 94.878515 | J19: =IF($B19="","",IF(OR($J$1="",$J$2=""),$B$1+3*$B$2,$J$1+3*$J$2)) -> 113.50198 | K19: =IF($B19="","",$C$1-3*$C$2) -> -6.9730071 | L19: =IF($B19="","",$C$1-2*$C$2) -> -4.5083205 | M19: =IF($B19="","",$C$1-$C$2) -> -2.0436339 | N19: =IF($B19="","",$C$1) -> 0.42105263 | O19: =IF($B19="","",$C$1+1*$C$2) -> 2.8857392 | P19: =IF($B19="","",$C$1+2*$C$2) -> 5.3504258 | Q19: =IF($B19="","",$C$1+3*$C$2) -> 7.8151124
A20: 45139 | B20: =IF('Catalogo de Variaveis'!H25="","",SUM('Catalogo de Variaveis'!H22:H25)) -> 54 | C20: =IFERROR(IF($B20="","",AVERAGE('Catalogo de Variaveis'!H25-'Catalogo de Variaveis'!H24,'Catalogo de Variaveis'!H24-'Catalogo de Variaveis'!H23,'Catalogo de Variaveis'!H23-'Catalogo de Variaveis'!H22,'Catalogo de Variaveis'!H22-'Catalogo de Variaveis'!H21)),0) -> 0.5 | D20: =IF($B20="","",IF(OR($J$1="",$J$2=""),$B$1-3*$B$2,$J$1-3*$J$2)) -> 1.7611741 | E20: =IF($B20="","",IF(OR($J$1="",$J$2=""),$B$1-2*$B$2,$J$1-2*$J$2)) -> 20.384642 | F20: =IF($B20="","",IF(OR($J$1="",$J$2=""),$B$1-$B$2,$J$1-$J$2)) -> 39.008111 | G20: =IF($B20="","",IF(OR($J$1="",$J$2=""),$B$1,$J$1)) -> 57.631579 | H20: =IF($B20="","",IF(OR($J$1="",$J$2=""),$B$1+$B$2,$J$1+$J$2)) -> 76.255047 | I20: =IF($B20="","",IF(OR($J$1="",$J$2=""),$B$1+2*$B$2,$J$1+2*$J$2)) -> 94.878515 | J20: =IF($B20="","",IF(OR($J$1="",$J$2=""),$B$1+3*$B$2,$J$1+3*$J$2)) -> 113.50198 | K20: =IF($B20="","",$C$1-3*$C$2) -> -6.9730071 | L20: =IF($B20="","",$C$1-2*$C$2) -> -4.5083205 | M20: =IF($B20="","",$C$1-$C$2) -> -2.0436339 | N20: =IF($B20="","",$C$1) -> 0.42105263 | O20: =IF($B20="","",$C$1+1*$C$2) -> 2.8857392 | P20: =IF($B20="","",$C$1+2*$C$2) -> 5.3504258 | Q20: =IF($B20="","",$C$1+3*$C$2) -> 7.8151124
... A96: 47453 | B96: =IF('Catalogo de Variaveis'!H101="","",SUM('Catalogo de Variaveis'!H98:H101)) | C96: =IFERROR(IF($B96="","",AVERAGE('Catalogo de Variaveis'!H101-'Catalogo de Variaveis'!H100,'Catalogo de Variaveis'!H100-'Catalogo de Variaveis'!H99,'Catalogo de Variaveis'!H99-'Catalogo de Variaveis'!H98,'Catalogo de Variaveis'!H98-'Catalogo de Variaveis'!H97)),0) | D96: =IF($B96="","",IF(OR($J$1="",$J$2=""),$B$1-3*$B$2,$J$1-3*$J$2)) | E96: =IF($B96="","",IF(OR($J$1="",$J$2=""),$B$1-2*$B$2,$J$1-2*$J$2)) | F96: =IF($B96="","",IF(OR($J$1="",$J$2=""),$B$1-$B$2,$J$1-$J$2)) | G96: =IF($B96="","",IF(OR($J$1="",$J$2=""),$B$1,$J$1)) | H96: =IF($B96="","",IF(OR($J$1="",$J$2=""),$B$1+$B$2,$J$1+$J$2)) | I96: =IF($B96="","",IF(OR($J$1="",$J$2=""),$B$1+2*$B$2,$J$1+2*$J$2)) | J96: =IF($B96="","",IF(OR($J$1="",$J$2=""),$B$1+3*$B$2,$J$1+3*$J$2)) | K96: =IF($B96="","",$C$1-3*$C$2) | L96: =IF($B96="","",$C$1-2*$C$2) | M96: =IF($B96="","",$C$1-$C$2) | N96: =IF($B96="","",$C$1) | O96: =IF($B96="","",$C$1+1*$C$2) | P96: =IF($B96="","",$C$1+2*$C$2) | Q96: =IF($B96="","",$C$1+3*$C$2)

Sheet V03
A1: Média | B1: =AVERAGE(B9:B1048576) -> 1.4210526 | C1: =AVERAGE(C9:C1048576) -> 0.013157895 | I1: LME | J1: =IF(LME="","",LME)
A2: Desvio Padrão | B2: =_xlfn.STDEV.S(B9:B1048576) -> 1.0301293 | C2: =_xlfn.STDEV.S(C9:C1048576) -> 0.20914375 | I2: VME | J2: =IF(VME="","",VME/3)
A3: Máximo | B3: =MAX(B9:B1048576) -> 4 | C3: =MAX(C9:C1048576) -> 0.5
A4: Mínimo | B4: =MIN(B9:B1048576) -> 0 | C4: =MIN(C9:C1048576) -> -0.25
A5: V03 - NÚMERO DE DENÚNCIAS DE ASSÉDIO SEXUAL APURADAS NO PERÍODO RECEBIDAS PELOS DIVERSOS CANAIS DE DENÚNCIAS DA COMPANHIA
A7: DADOS | D7: SOMA | K7: AMPLITUDE
A8: Período | B8: Soma | C8: Amplitude | D8: LIC | E8: L2I | F8: L1I | G8: LMC | H8: L1S | I8: L2S | J8: LSC | K8: LIC | L8: L2I | M8: L1I | N8: LMC | O8: L1S | P8: L2S | Q8: LSC
A9: 44805 | B9: =IF('Catalogo de Variaveis'!I14="","",SUM('Catalogo de Variaveis'!I11:I14)) -> 0 | C9: =IFERROR(IF($B9="","",AVERAGE('Catalogo de Variaveis'!I14-'Catalogo de Variaveis'!I13,'Catalogo de Variaveis'!I13-'Catalogo de Variaveis'!I12,'Catalogo de Variaveis'!I12-'Catalogo de Variaveis'!I11,'Catalogo de Variaveis'!I11-'Catalogo de Variaveis'!I10)),0) -> 0 | D9: =IF($B9="","",IF(OR($J$1="",$J$2=""),$B$1-3*$B$2,$J$1-3*$J$2)) -> -1.6693353 | E9: =IF($B9="","",IF(OR($J$1="",$J$2=""),$B$1-2*$B$2,$J$1-2*$J$2)) -> -0.63920602 | F9: =IF($B9="","",IF(OR($J$1="",$J$2=""),$B$1-$B$2,$J$1-$J$2)) -> 0.3909233 | G9: =IF($B9="","",IF(OR($J$1="",$J$2=""),$B$1,$J$1)) -> 1.4210526 | H9: =IF($B9="","",IF(OR($J$1="",$J$2=""),$B$1+$B$2,$J$1+$J$2)) -> 2.451182 | I9: =IF($B9="","",IF(OR($J$1="",$J$2=""),$B$1+2*$B$2,$J$1+2*$J$2)) -> 3.4813113 | J9: =IF($B9="","",IF(OR($J$1="",$J$2=""),$B$1+3*$B$2,$J$1+3*$J$2)) -> 4.5114406 | K9: =IF($B9="","",$C$1-3*$C$2) -> -0.61427337 | L9: =IF($B9="","",$C$1-2*$C$2) -> -0.40512961 | M9: =IF($B9="","",$C$1-$C$2) -> -0.19598586 | N9: =IF($B9="","",$C$1) -> 0.013157895 | O9: =IF($B9="","",$C$1+1*$C$2) -> 0.22230165 | P9: =IF($B9="","",$C$1+2*$C$2) -> 0.4314454 | Q9: =IF($B9="","",$C$1+3*$C$2) -> 0.64058915
A10: 44835 | B10: =IF('Catalogo de Variaveis'!I15="","",SUM('Catalogo de Variaveis'!I12:I15)) -> 1 | C10: =IFERROR(IF($B10="","",AVERAGE('Catalogo de Variaveis'!I15-'Catalogo de Variaveis'!I14,'Catalogo de Variaveis'!I14-'Catalogo de Variaveis'!I13,'Catalogo de Variaveis'!I13-'Catalogo de Variaveis'!I12,'Catalogo de Variaveis'!I12-'Catalogo de Variaveis'!I11)),0) -> 0.25 | D10: =IF($B10="","",IF(OR($J$1="",$J$2=""),$B$1-3*$B$2,$J$1-3*$J$2)) -> -1.6693353 | E10: =IF($B10="","",IF(OR($J$1="",$J$2=""),$B$1-2*$B$2,$J$1-2*$J$2)) -> -0.63920602 | F10: =IF($B10="","",IF(OR($J$1="",$J$2=""),$B$1-$B$2,$J$1-$J$2)) -> 0.3909233 | G10: =IF($B10="","",IF(OR($J$1="",$J$2=""),$B$1,$J$1)) -> 1.4210526 | H10: =IF($B10="","",IF(OR($J$1="",$J$2=""),$B$1+$B$2,$J$1+$J$2)) -> 2.451182 | I10: =IF($B10="","",IF(OR($J$1="",$J$2=""),$B$1+2*$B$2,$J$1+2*$J$2)) -> 3.4813113 | J10: =IF($B10="","",IF(OR($J$1="",$J$2=""),$B$1+3*$B$2,$J$1+3*$J$2)) -> 4.5114406 | K10: =IF($B10="","",$C$1-3*$C$2) -> -0.61427337 | L10: =IF($B10="","",$C$1-2*$C$2) -> -0.40512961 | M10: =IF($B10="","",$C$1-$C$2) -> -0.19598586 | N10: =IF($B10="","",$C$1) -> 0.013157895 | O10: =IF($B10="","",$C$1+1*$C$2) -> 0.22230165 | P10: =IF($B10="","",$C$1+2*$C$2) -> 0.4314454 | Q10: =IF($B10="","",$C$1+3*$C$2) -> 0.64058915
A11: 44866 | B11: =IF('Catalogo de Variaveis'!I16="","",SUM('Catalogo de Variaveis'!I13:I16)) -> 1 | C11: =IFERROR(IF($B11="","",AVERAGE('Catalogo de Variaveis'!I16-'Catalogo de Variaveis'!I15,'Catalogo de Variaveis'!I15-'Catalogo de Variaveis'!I14,'Catalogo de Variaveis'!I14-'Catalogo de Variaveis'!I13,'Catalogo de Variaveis'!I13-'Catalogo de Variaveis'!I12)),0) -> 0 | D11: =IF($B11="","",IF(OR($J$1="",$J$2=""),$B$1-3*$B$2,$J$1-3*$J$2)) -> -1.6693353 | E11: =IF($B11="","",IF(OR($J$1="",$J$2=""),$B$1-2*$B$2,$J$1-2*$J$2)) -> -0.63920602 | F11: =IF($B11="","",IF(OR($J$1="",$J$2=""),$B$1-$B$2,$J$1-$J$2)) -> 0.3909233 | G11: =IF($B11="","",IF(OR($J$1="",$J$2=""),$B$1,$J$1)) -> 1.4210526 | H11: =IF($B11="","",IF(OR($J$1="",$J$2=""),$B$1+$B$2,$J$1+$J$2)) -> 2.451182 | I11: =IF($B11="","",IF(OR($J$1="",$J$2=""),$B$1+2*$B$2,$J$1+2*$J$2)) -> 3.4813113 | J11: =IF($B11="","",IF(OR($J$1="",$J$2=""),$B$1+3*$B$2,$J$1+3*$J$2)) -> 4.5114406 | K11: =IF($B11="","",$C$1-3*$C$2) -> -0.61427337 | L11: =IF($B11="","",$C$1-2*$C$2) -> -0.40512961 | M11: =IF($B11="","",$C$1-$C$2) -> -0.19598586 | N11: =IF($B11="","",$C$1) -> 0.013157895 | O11: =IF($B11="","",$C$1+1*$C$2) -> 0.22230165 | P11: =IF($B11="","",$C$1+2*$C$2) -> 0.4314454 | Q11: =IF($B11="","",$C$1+3*$C$2) -> 0.64058915
A12: 44896 | B12: =IF('Catalogo de Variaveis'!I17="","",SUM('Catalogo de Variaveis'!I14:I17)) -> 2 | C12: =IFERROR(IF($B12="","",AVERAGE('Catalogo de Variaveis'!I17-'Catalogo de Variaveis'!I16,'Catalogo de Variaveis'!I16-'Catalogo de Variaveis'!I15,'Catalogo de Variaveis'!I15-'Catalogo de Variaveis'!I14,'Catalogo de Variaveis'!I14-'Catalogo de Variaveis'!I13)),0) -> 0.25 | D12: =IF($B12="","",IF(OR($J$1="",$J$2=""),$B$1-3*$B$2,$J$1-3*$J$2)) -> -1.6693353 | E12: =IF($B12="","",IF(OR($J$1="",$J$2=""),$B$1-2*$B$2,$J$1-2*$J$2)) -> -0.63920602 | F12: =IF($B12="","",IF(OR($J$1="",$J$2=""),$B$1-$B$2,$J$1-$J$2)) -> 0.3909233 | G12: =IF($B12="","",IF(OR($J$1="",$J$2=""),$B$1,$J$1)) -> 1.4210526 | H12: =IF($B12="","",IF(OR($J$1="",$J$2=""),$B$1+$B$2,$J$1+$J$2)) -> 2.451182 | I12: =IF($B12="","",IF(OR($J$1="",$J$2=""),$B$1+2*$B$2,$J$1+2*$J$2)) -> 3.4813113 | J12: =IF($B12="","",IF(OR($J$1="",$J$2=""),$B$1+3*$B$2,$J$1+3*$J$2)) -> 4.5114406 | K12: =IF($B12="","",$C$1-3*$C$2) -> -0.61427337 | L12: =IF($B12="","",$C$1-2*$C$2) -> -0.40512961 | M12: =IF($B12="","",$C$1-$C$2) -> -0.19598586 | N12: =IF($B12="","",$C$1) -> 0.013157895 | O12: =IF($B12="","",$C$1+1*$C$2) -> 0.22230165 | P12: =IF($B12="","",$C$1+2*$C$2) -> 0.4314454 | Q12: =IF($B12="","",$C$1+3*$C$2) -> 0.64058915
A13: 44927 | B13: =IF('Catalogo de Variaveis'!I18="","",SUM('Catalogo de Variaveis'!I15:I18)) -> 2 | C13: =IFERROR(IF($B13="","",AVERAGE('Catalogo de Variaveis'!I18-'Catalogo de Variaveis'!I17,'Catalogo de Variaveis'!I17-'Catalogo de Variaveis'!I16,'Catalogo de Variaveis'!I16-'Catalogo de Variaveis'!I15,'Catalogo de Variaveis'!I15-'Catalogo de Variaveis'!I14)),0) -> 0 | D13: =IF($B13="","",IF(OR($J$1="",$J$2=""),$B$1-3*$B$2,$J$1-3*$J$2)) -> -1.6693353 | E13: =IF($B13="","",IF(OR($J$1="",$J$2=""),$B$1-2*$B$2,$J$1-2*$J$2)) -> -0.63920602 | F13: =IF($B13="","",IF(OR($J$1="",$J$2=""),$B$1-$B$2,$J$1-$J$2)) -> 0.3909233 | G13: =IF($B13="","",IF(OR($J$1="",$J$2=""),$B$1,$J$1)) -> 1.4210526 | H13: =IF($B13="","",IF(OR($J$1="",$J$2=""),$B$1+$B$2,$J$1+$J$2)) -> 2.451182 | I13: =IF($B13="","",IF(OR($J$1="",$J$2=""),$B$1+2*$B$2,$J$1+2*$J$2)) -> 3.4813113 | J13: =IF($B13="","",IF(OR($J$1="",$J$2=""),$B$1+3*$B$2,$J$1+3*$J$2)) -> 4.5114406 | K13: =IF($B13="","",$C$1-3*$C$2) -> -0.61427337 | L13: =IF($B13="","",$C$1-2*$C$2) -> -0.40512961 | M13: =IF($B13="","",$C$1-$C$2) -> -0.19598586 | N13: =IF($B13="","",$C$1) -> 0.013157895 | O13: =IF($B13="","",$C$1+1*$C$2) -> 0.22230165 | P13: =IF($B13="","",$C$1+2*$C$2) -> 0.4314454 | Q13: =IF($B13="","",$C$1+3*$C$2) -> 0.64058915
A14: 44958 | B14: =IF('Catalogo de Variaveis'!I19="","",SUM('Catalogo de Variaveis'!I16:I19)) -> 1 | C14: =IFERROR(IF($B14="","",AVERAGE('Catalogo de Variaveis'!I19-'Catalogo de Variaveis'!I18,'Catalogo de Variaveis'!I18-'Catalogo de Variaveis'!I17,'Catalogo de Variaveis'!I17-'Catalogo de Variaveis'!I16,'Catalogo de Variaveis'!I16-'Catalogo de Variaveis'!I15)),0) -> -0.25 | D14: =IF($B14="","",IF(OR($J$1="",$J$2=""),$B$1-3*$B$2,$J$1-3*$J$2)) -> -1.6693353 | E14: =IF($B14="","",IF(OR($J$1="",$J$2=""),$B$1-2*$B$2,$J$1-2*$J$2)) -> -0.63920602 | F14: =IF($B14="","",IF(OR($J$1="",$J$2=""),$B$1-$B$2,$J$1-$J$2)) -> 0.3909233 | G14: =IF($B14="","",IF(OR($J$1="",$J$2=""),$B$1,$J$1)) -> 1.4210526 | H14: =IF($B14="","",IF(OR($J$1="",$J$2=""),$B$1+$B$2,$J$1+$J$2)) -> 2.451182 | I14: =IF($B14="","",IF(OR($J$1="",$J$2=""),$B$1+2*$B$2,$J$1+2*$J$2)) -> 3.4813113 | J14: =IF($B14="","",IF(OR($J$1="",$J$2=""),$B$1+3*$B$2,$J$1+3*$J$2)) -> 4.5114406 | K14: =IF($B14="","",$C$1-3*$C$2) -> -0.61427337 | L14: =IF($B14="","",$C$1-2*$C$2) -> -0.40512961 | M14: =IF($B14="","",$C$1-$C$2) -> -0.19598586 | N14: =IF($B14="","",$C$1) -> 0.013157895 | O14: =IF($B14="","",$C$1+1*$C$2) -> 0.22230165 | P14: =IF($B14="","",$C$1+2*$C$2) -> 0.4314454 | Q14: =IF($B14="","",$C$1+3*$C$2) -> 0.64058915
A15: 44986 | B15: =IF('Catalogo de Variaveis'!I20="","",SUM('Catalogo de Variaveis'!I17:I20)) -> 1 | C15: =IFERROR(IF($B15="","",AVERAGE('Catalogo de Variaveis'!I20-'Catalogo de Variaveis'!I19,'Catalogo de Variaveis'!I19-'Catalogo de Variaveis'!I18,'Catalogo de Variaveis'!I18-'Catalogo de Variaveis'!I17,'Catalogo de Variaveis'!I17-'Catalogo de Variaveis'!I16)),0) -> 0 | D15: =IF($B15="","",IF(OR($J$1="",$J$2=""),$B$1-3*$B$2,$J$1-3*$J$2)) -> -1.6693353 | E15: =IF($B15="","",IF(OR($J$1="",$J$2=""),$B$1-2*$B$2,$J$1-2*$J$2)) -> -0.63920602 | F15: =IF($B15="","",IF(OR($J$1="",$J$2=""),$B$1-$B$2,$J$1-$J$2)) -> 0.3909233 | G15: =IF($B15="","",IF(OR($J$1="",$J$2=""),$B$1,$J$1)) -> 1.4210526 | H15: =IF($B15="","",IF(OR($J$1="",$J$2=""),$B$1+$B$2,$J$1+$J$2)) -> 2.451182 | I15: =IF($B15="","",IF(OR($J$1="",$J$2=""),$B$1+2*$B$2,$J$1+2*$J$2)) -> 3.4813113 | J15: =IF($B15="","",IF(OR($J$1="",$J$2=""),$B$1+3*$B$2,$J$1+3*$J$2)) -> 4.5114406 | K15: =IF($B15="","",$C$1-3*$C$2) -> -0.61427337 | L15: =IF($B15="","",$C$1-2*$C$2) -> -0.40512961 | M15: =IF($B15="","",$C$1-$C$2) -> -0.19598586 | N15: =IF($B15="","",$C$1) -> 0.013157895 | O15: =IF($B15="","",$C$1+1*$C$2) -> 0.22230165 | P15: =IF($B15="","",$C$1+2*$C$2) -> 0.4314454 | Q15: =IF($B15="","",$C$1+3*$C$2) -> 0.64058915
A16: 45017 | B16: =IF('Catalogo de Variaveis'!I21="","",SUM('Catalogo de Variaveis'!I18:I21)) -> 0 | C16: =IFERROR(IF($B16="","",AVERAGE('Catalogo de Variaveis'!I21-'Catalogo de Variaveis'!I20,'Catalogo de Variaveis'!I20-'Catalogo de Variaveis'!I19,'Catalogo de Variaveis'!I19-'Catalogo de Variaveis'!I18,'Catalogo de Variaveis'!I18-'Catalogo de Variaveis'!I17)),0) -> -0.25 | D16: =IF($B16="","",IF(OR($J$1="",$J$2=""),$B$1-3*$B$2,$J$1-3*$J$2)) -> -1.6693353 | E16: =IF($B16="","",IF(OR($J$1="",$J$2=""),$B$1-2*$B$2,$J$1-2*$J$2)) -> -0.63920602 | F16: =IF($B16="","",IF(OR($J$1="",$J$2=""),$B$1-$B$2,$J$1-$J$2)) -> 0.3909233 | G16: =IF($B16="","",IF(OR($J$1="",$J$2=""),$B$1,$J$1)) -> 1.4210526 | H16: =IF($B16="","",IF(OR($J$1="",$J$2=""),$B$1+$B$2,$J$1+$J$2)) -> 2.451182 | I16: =IF($B16="","",IF(OR($J$1="",$J$2=""),$B$1+2*$B$2,$J$1+2*$J$2)) -> 3.4813113 | J16: =IF($B16="","",IF(OR($J$1="",$J$2=""),$B$1+3*$B$2,$J$1+3*$J$2)) -> 4.5114406 | K16: =IF($B16="","",$C$1-3*$C$2) -> -0.61427337 | L16: =IF($B16="","",$C$1-2*$C$2) -> -0.40512961 | M16: =IF($B16="","",$C$1-$C$2) -> -0.19598586 | N16: =IF($B16="","",$C$1) -> 0.013157895 | O16: =IF($B16="","",$C$1+1*$C$2) -> 0.22230165 | P16: =IF($B16="","",$C$1+2*$C$2) -> 0.4314454 | Q16: =IF($B16="","",$C$1+3*$C$2) -> 0.64058915
A17: 45047 | B17: =IF('Catalogo de Variaveis'!I22="","",SUM('Catalogo de Variaveis'!I19:I22)) -> 0 | C17: =IFERROR(IF($B17="","",AVERAGE('Catalogo de Variaveis'!I22-'Catalogo de Variaveis'!I21,'Catalogo de Variaveis'!I21-'Catalogo de Variaveis'!I20,'Catalogo de Variaveis'!I20-'Catalogo de Variaveis'!I19,'Catalogo de Variaveis'!I19-'Catalogo de Variaveis'!I18)),0) -> 0 | D17: =IF($B17="","",IF(OR($J$1="",$J$2=""),$B$1-3*$B$2,$J$1-3*$J$2)) -> -1.6693353 | E17: =IF($B17="","",IF(OR($J$1="",$J$2=""),$B$1-2*$B$2,$J$1-2*$J$2)) -> -0.63920602 | F17: =IF($B17="","",IF(OR($J$1="",$J$2=""),$B$1-$B$2,$J$1-$J$2)) -> 0.3909233 | G17: =IF($B17="","",IF(OR($J$1="",$J$2=""),$B$1,$J$1)) -> 1.4210526 | H17: =IF($B17="","",IF(OR($J$1="",$J$2=""),$B$1+$B$2,$J$1+$J$2)) -> 2.451182 | I17: =IF($B17="","",IF(OR($J$1="",$J$2=""),$B$1+2*$B$2,$J$1+2*$J$2)) -> 3.4813113 | J17: =IF($B17="","",IF(OR($J$1="",$J$2=""),$B$1+3*$B$2,$J$1+3*$J$2)) -> 4.5114406 | K17: =IF($B17="","",$C$1-3*$C$2) -> -0.61427337 | L17: =IF($B17="","",$C$1-2*$C$2) -> -0.40512961 | M17: =IF($B17="","",$C$1-$C$2) -> -0.19598586 | N17: =IF($B17="","",$C$1) -> 0.013157895 | O17: =IF($B17="","",$C$1+1*$C$2) -> 0.22230165 | P17: =IF($B17="","",$C$1+2*$C$2) -> 0.4314454 | Q17: =IF($B17="","",$C$1+3*$C$2) -> 0.64058915
A18: 45078 | B18: =IF('Catalogo de Variaveis'!I23="","",SUM('Catalogo de Variaveis'!I20:I23)) -> 2 | C18: =IFERROR(IF($B18="","",AVERAGE('Catalogo de Variaveis'!I23-'Catalogo de Variaveis'!I22,'Catalogo de Variaveis'!I22-'Catalogo de Variaveis'!I21,'Catalogo de Variaveis'!I21-'Catalogo de Variaveis'!I20,'Catalogo de Variaveis'!I20-'Catalogo de Variaveis'!I19)),0) -> 0.5 | D18: =IF($B18="","",IF(OR($J$1="",$J$2=""),$B$1-3*$B$2,$J$1-3*$J$2)) -> -1.6693353 | E18: =IF($B18="","",IF(OR($J$1="",$J$2=""),$B$1-2*$B$2,$J$1-2*$J$2)) -> -0.63920602 | F18: =IF($B18="","",IF(OR($J$1="",$J$2=""),$B$1-$B$2,$J$1-$J$2)) -> 0.3909233 | G18: =IF($B18="","",IF(OR($J$1="",$J$2=""),$B$1,$J$1)) -> 1.4210526 | H18: =IF($B18="","",IF(OR($J$1="",$J$2=""),$B$1+$B$2,$J$1+$J$2)) -> 2.451182 | I18: =IF($B18="","",IF(OR($J$1="",$J$2=""),$B$1+2*$B$2,$J$1+2*$J$2)) -> 3.4813113 | J18: =IF($B18="","",IF(OR($J$1="",$J$2=""),$B$1+3*$B$2,$J$1+3*$J$2)) -> 4.5114406 | K18: =IF($B18="","",$C$1-3*$C$2) -> -0.61427337 | L18: =IF($B18="","",$C$1-2*$C$2) -> -0.40512961 | M18: =IF($B18="","",$C$1-$C$2) -> -0.19598586 | N18: =IF($B18="","",$C$1) -> 0.013157895 | O18: =IF($B18="","",$C$1+1*$C$2) -> 0.22230165 | P18: =IF($B18="","",$C$1+2*$C$2) -> 0.4314454 | Q18: =IF($B18="","",$C$1+3*$C$2) -> 0.64058915
A19: 45108 | B19: =IF('Catalogo de Variaveis'!I24="","",SUM('Catalogo de Variaveis'!I21:I24)) -> 3 | C19: =IFERROR(IF($B19="","",AVERAGE('Catalogo de Variaveis'!I24-'Catalogo de Variaveis'!I23,'Catalogo de Variaveis'!I23-'Catalogo de Variaveis'!I22,'Catalogo de Variaveis'!I22-'Catalogo de Variaveis'!I21,'Catalogo de Variaveis'!I21-'Catalogo de Variaveis'!I20)),0) -> 0.25 | D19: =IF($B19="","",IF(OR($J$1="",$J$2=""),$B$1-3*$B$2,$J$1-3*$J$2)) -> -1.6693353 | E19: =IF($B19="","",IF(OR($J$1="",$J$2=""),$B$1-2*$B$2,$J$1-2*$J$2)) -> -0.63920602 | F19: =IF($B19="","",IF(OR($J$1="",$J$2=""),$B$1-$B$2,$J$1-$J$2)) -> 0.3909233 | G19: =IF($B19="","",IF(OR($J$1="",$J$2=""),$B$1,$J$1)) -> 1.4210526 | H19: =IF($B19="","",IF(OR($J$1="",$J$2=""),$B$1+$B$2,$J$1+$J$2)) -> 2.451182 | I19: =IF($B19="","",IF(OR($J$1="",$J$2=""),$B$1+2*$B$2,$J$1+2*$J$2)) -> 3.4813113 | J19: =IF($B19="","",IF(OR($J$1="",$J$2=""),$B$1+3*$B$2,$J$1+3*$J$2)) -> 4.5114406 | K19: =IF($B19="","",$C$1-3*$C$2) -> -0.61427337 | L19: =IF($B19="","",$C$1-2*$C$2) -> -0.40512961 | M19: =IF($B19="","",$C$1-$C$2) -> -0.19598586 | N19: =IF($B19="","",$C$1) -> 0.013157895 | O19: =IF($B19="","",$C$1+1*$C$2) -> 0.22230165 | P19: =IF($B19="","",$C$1+2*$C$2) -> 0.4314454 | Q19: =IF($B19="","",$C$1+3*$C$2) -> 0.64058915
A20: 45139 | B20: =IF('Catalogo de Variaveis'!I25="","",SUM('Catalogo de Variaveis'!I22:I25)) -> 3 | C20: =IFERROR(IF($B20="","",AVERAGE('Catalogo de Variaveis'!I25-'Catalogo de Variaveis'!I24,'Catalogo de Variaveis'!I24-'Catalogo de Variaveis'!I23,'Catalogo de Variaveis'!I23-'Catalogo de Variaveis'!I22,'Catalogo de Variaveis'!I22-'Catalogo de Variaveis'!I21)),0) -> 0 | D20: =IF($B20="","",IF(OR($J$1="",$J$2=""),$B$1-3*$B$2,$J$1-3*$J$2)) -> -1.6693353 | E20: =IF($B20="","",IF(OR($J$1="",$J$2=""),$B$1-2*$B$2,$J$1-2*$J$2)) -> -0.63920602 | F20: =IF($B20="","",IF(OR($J$1="",$J$2=""),$B$1-$B$2,$J$1-$J$2)) -> 0.3909233 | G20: =IF($B20="","",IF(OR($J$1="",$J$2=""),$B$1,$J$1)) -> 1.4210526 | H20: =IF($B20="","",IF(OR($J$1="",$J$2=""),$B$1+$B$2,$J$1+$J$2)) -> 2.451182 | I20: =IF($B20="","",IF(OR($J$1="",$J$2=""),$B$1+2*$B$2,$J$1+2*$J$2)) -> 3.4813113 | J20: =IF($B20="","",IF(OR($J$1="",$J$2=""),$B$1+3*$B$2,$J$1+3*$J$2)) -> 4.5114406 | K20: =IF($B20="","",$C$1-3*$C$2) -> -0.61427337 | L20: =IF($B20="","",$C$1-2*$C$2) -> -0.40512961 | M20: =IF($B20="","",$C$1-$C$2) -> -0.19598586 | N20: =IF($B20="","",$C$1) -> 0.013157895 | O20: =IF($B20="","",$C$1+1*$C$2) -> 0.22230165 | P20: =IF($B20="","",$C$1+2*$C$2) -> 0.4314454 | Q20: =IF($B20="","",$C$1+3*$C$2) -> 0.64058915
... A96: 47453 | B96: =IF('Catalogo de Variaveis'!I101="","",SUM('Catalogo de Variaveis'!I98:I101)) | C96: =IFERROR(IF($B96="","",AVERAGE('Catalogo de Variaveis'!I101-'Catalogo de Variaveis'!I100,'Catalogo de Variaveis'!I100-'Catalogo de Variaveis'!I99,'Catalogo de Variaveis'!I99-'Catalogo de Variaveis'!I98,'Catalogo de Variaveis'!I98-'Catalogo de Variaveis'!I97)),0) | D96: =IF($B96="","",IF(OR($J$1="",$J$2=""),$B$1-3*$B$2,$J$1-3*$J$2)) | E96: =IF($B96="","",IF(OR($J$1="",$J$2=""),$B$1-2*$B$2,$J$1-2*$J$2)) | F96: =IF($B96="","",IF(OR($J$1="",$J$2=""),$B$1-$B$2,$J$1-$J$2)) | G96: =IF($B96="","",IF(OR($J$1="",$J$2=""),$B$1,$J$1)) | H96: =IF($B96="","",IF(OR($J$1="",$J$2=""),$B$1+$B$2,$J$1+$J$2)) | I96: =IF($B96="","",IF(OR($J$1="",$J$2=""),$B$1+2*$B$2,$J$1+2*$J$2)) | J96: =IF($B96="","",IF(OR($J$1="",$J$2=""),$B$1+3*$B$2,$J$1+3*$J$2)) | K96: =IF($B96="","",$C$1-3*$C$2) | L96: =IF($B96="","",$C$1-2*$C$2) | M96: =IF($B96="","",$C$1-$C$2) | N96: =IF($B96="","",$C$1) | O96: =IF($B96="","",$C$1+1*$C$2) | P96: =IF($B96="","",$C$1+2*$C$2) | Q96: =IF($B96="","",$C$1+3*$C$2)

Sheet V04
A1: Média | B1: =AVERAGE(B9:B1048576) -> 57.631579 | C1: =AVERAGE(C9:C1048576) -> 0.42105263 | I1: LME | J1: =IF(LME="","",LME)
A2: Desvio Padrão | B2: =_xlfn.STDEV.S(B9:B1048576) -> 18.623468 | C2: =_xlfn.STDEV.S(C9:C1048576) -> 2.4646866 | I2: VME | J2: =IF(VME="","",VME/3)
A3: Máximo | B3: =MAX(B9:B1048576) -> 103 | C3: =MAX(C9:C1048576) -> 4.25
A4: Mínimo | B4: =MIN(B9:B1048576) -> 16 | C4: =MIN(C9:C1048576) -> -6
